Workbook
Name ApplicablePTList1: AND(LEN('[1]Changes to the template'!$B1)>0,NOT('[1]Changes to the template'!$B1="NON_RIDING_TOY_VEHICLE"))
Name CONDITION_LIST_0: '[1]Conditions List'!$A$2
Name CONDITION_LIST_1: '[1]Conditions List'!$B$2:$B$3
Name CONDITION_LIST_10: '[1]Conditions List'!$K$2:$K$4
Name CONDITION_LIST_11: '[1]Conditions List'!$L$2:$L$3
Name CONDITION_LIST_12: '[1]Conditions List'!$M$2:$M$7
Name CONDITION_LIST_13: '[1]Conditions List'!$N$2:$N$10
Name CONDITION_LIST_14: '[1]Conditions List'!$O$2:$O$4
Name CONDITION_LIST_15: '[1]Conditions List'!$P$2:$P$5
Name CONDITION_LIST_16: '[1]Conditions List'!$Q$2
Name CONDITION_LIST_17: '[1]Conditions List'!$R$2
Name CONDITION_LIST_18: '[1]Conditions List'!$S$2
Name CONDITION_LIST_19: '[1]Conditions List'!$T$2:$T$6
Name CONDITION_LIST_2: '[1]Conditions List'!$C$2:$C$9
Name CONDITION_LIST_20: '[1]Conditions List'!$U$2:$U$14
Name CONDITION_LIST_21: '[1]Conditions List'!$V$2:$V$6
Name CONDITION_LIST_22: '[1]Conditions List'!$W$2:$W$5
Name CONDITION_LIST_23: '[1]Conditions List'!$X$2
Name CONDITION_LIST_24: '[1]Conditions List'!$Y$2:$Y$11
Name CONDITION_LIST_25: '[1]Conditions List'!$Z$2:$Z$3
Name CONDITION_LIST_26: '[1]Conditions List'!$AA$2:$AA$5
Name CONDITION_LIST_27: '[1]Conditions List'!$AB$2:$AB$4
Name CONDITION_LIST_28: '[1]Conditions List'!$AC$2
Name CONDITION_LIST_29: '[1]Conditions List'!$AD$2
Name CONDITION_LIST_3: '[1]Conditions List'!$D$2:$D$3
Name CONDITION_LIST_30: '[1]Conditions List'!$AE$2:$AE$4
Name CONDITION_LIST_31: '[1]Conditions List'!$AF$2:$AF$3
Name CONDITION_LIST_32: '[1]Conditions List'!$AG$2
Name CONDITION_LIST_33: '[1]Conditions List'!$AH$2
Name CONDITION_LIST_34: '[1]Conditions List'!$AI$2
Name CONDITION_LIST_35: '[1]Conditions List'!$AJ$2:$AJ$3
Name CONDITION_LIST_36: '[1]Conditions List'!$AK$2:$AK$8
Name CONDITION_LIST_37: '[1]Conditions List'!$AL$2
Name CONDITION_LIST_38: '[1]Conditions List'!$AM$2
Name CONDITION_LIST_39: '[1]Conditions List'!$AN$2
Name CONDITION_LIST_4: '[1]Conditions List'!$E$2:$E$17
Name CONDITION_LIST_40: '[1]Conditions List'!$AO$2
Name CONDITION_LIST_5: '[1]Conditions List'!$F$2:$F$11
Name CONDITION_LIST_6: '[1]Conditions List'!$G$2
Name CONDITION_LIST_7: '[1]Conditions List'!$H$2
Name CONDITION_LIST_8: '[1]Conditions List'!$I$2:$I$5
Name CONDITION_LIST_9: '[1]Conditions List'!$J$2
Name for_maxfPTList0batterymarketplace_idATVPDKIKX0DER1.cell_composition_other_than_listedlanguage_tagen_US1.value: AND(AND(OR(AND(AND(IF(COUNTIF([1]!CONDITION_LIST_37,'[1]Changes to the template'!$FQ1)>0,FALSE,TRUE)))),'[1]Changes to the template'!$B1<>""))
Name for_maxfPTList0child_parent_sku_relationshipmarketplace_idATVPDKIKX0DER1.parent_sku: AND(AND(OR(AND(OR(OR('[1]Changes to the template'!$D1<>"Child",'[1]Changes to the template'!$D1="")))),'[1]Changes to the template'!$B1<>""))
Name for_maxfPTList0compliance_age_rangemarketplace_idATVPDKIKX0DER1.value: AND(AND(OR(AND(AND(IF(COUNTIF([1]!CONDITION_LIST_35,'[1]Changes to the template'!$JN1)>0,FALSE,TRUE)))),'[1]Changes to the template'!$B1<>""))
Name for_maxfPTList0compliance_operation_modemarketplace_idATVPDKIKX0DER1.value: AND(AND(OR(AND(AND(IF(COUNTIF([1]!CONDITION_LIST_35,'[1]Changes to the template'!$JN1)>0,FALSE,TRUE)))),'[1]Changes to the template'!$B1<>""))
Name for_maxfPTList0compliance_recommended_agemarketplace_idATVPDKIKX0DER1.value: AND(AND(OR(AND(AND(IF(COUNTIF([1]!CONDITION_LIST_35,'[1]Changes to the template'!$JN1)>0,FALSE,TRUE)))),'[1]Changes to the template'!$B1<>""))
Name for_maxfPTList0compliance_toy_materialmarketplace_idATVPDKIKX0DER1.value: AND(AND(OR(AND(AND(IF(COUNTIF([1]!CONDITION_LIST_35,'[1]Changes to the template'!$JN1)>0,FALSE,TRUE)))),'[1]Changes to the template'!$B1<>""))
Name for_maxfPTList0compliance_toy_typemarketplace_idATVPDKIKX0DER1.value: AND(AND(OR(AND(AND(IF(COUNTIF([1]!CONDITION_LIST_35,'[1]Changes to the template'!$JN1)>0,FALSE,TRUE)))),'[1]Changes to the template'!$B1<>""))
Name for_maxfPTList0fulfillment_availability1.is_inventory_available: AND(AND(OR(AND(AND(IF(COUNTIF([1]!CONDITION_LIST_31,'[1]Changes to the template'!$DP1)>0,FALSE,TRUE))),AND(AND(NOT('[1]Changes to the template'!$DQ1="")))),'[1]Changes to the template'!$B1<>""))
Name for_maxfPTList0fulfillment_availability1.lead_time_to_ship_max_days: AND(AND(OR(AND(AND(IF(COUNTIF([1]!CONDITION_LIST_31,'[1]Changes to the template'!$DP1)>0,FALSE,TRUE)))),'[1]Changes to the template'!$B1<>""))
Name for_maxfPTList0fulfillment_availability1.quantity: AND(AND(OR(AND(AND(IF(COUNTIF([1]!CONDITION_LIST_31,'[1]Changes to the template'!$DP1)>0,FALSE,TRUE))),AND(AND(NOT('[1]Changes to the template'!$DT1="")))),'[1]Changes to the template'!$B1<>""))
Name for_maxfPTList0fulfillment_availability1.restock_date: AND(AND(OR(AND(AND(IF(COUNTIF([1]!CONDITION_LIST_31,'[1]Changes to the template'!$DP1)>0,FALSE,TRUE)))),'[1]Changes to the template'!$B1<>""))
Name for_minPTList0child_parent_sku_relationshipmarketplace_idATVPDKIKX0DER1.parent_sku: AND('[1]Changes to the template'!$B1<>"",OR(OR(AND(OR(OR(IF(COUNTIF([1]!CONDITION_LIST_20,'[1]Changes to the template'!$D1)>0,TRUE,FALSE)))))))
Name for_minPTList0fulfillment_availability1.is_inventory_available: AND('[1]Changes to the template'!$B1<>"",OR(OR(AND(OR(OR(IF(COUNTIF([1]!CONDITION_LIST_31,'[1]Changes to the template'!$DP1)>0,TRUE,FALSE))),OR(OR(('[1]Changes to the template'!$DQ1="")))))))
Name for_minPTList0fulfillment_availability1.quantity: AND('[1]Changes to the template'!$B1<>"",OR(OR(AND(OR(OR(IF(COUNTIF([1]!CONDITION_LIST_31,'[1]Changes to the template'!$DP1)>0,TRUE,FALSE))),OR(OR(('[1]Changes to the template'!$DT1="")))))))
Name for_minPTList0pesticide_markingmarketplace_idATVPDKIKX0DER1.certification_number: AND('[1]Changes to the template'!$B1<>"",OR(OR(AND(OR(OR(IF(COUNTIF([1]!for_minPTList0fulfillment_availability1.quantity,'[1]Changes to the template'!$HR1)>0,TRUE,FALSE)))))))
Name for_minPTList0pesticide_markingmarketplace_idATVPDKIKX0DER2.certification_number: AND('[1]Changes to the template'!$B1<>"",OR(OR(AND(OR(OR(IF(COUNTIF([1]!for_minPTList0fulfillment_availability1.quantity,'[1]Changes to the template'!$HU1)>0,TRUE,FALSE)))))))
Name for_minPTList0pesticide_markingmarketplace_idATVPDKIKX0DER3.certification_number: AND('[1]Changes to the template'!$B1<>"",OR(OR(AND(OR(OR(IF(COUNTIF([1]!for_minPTList0fulfillment_availability1.quantity,'[1]Changes to the template'!$HX1)>0,TRUE,FALSE)))))))
Name form_rgPTList0amzn1.volt.ca.product_id_type: AND(AND(AND((AND(OR(OR(OR(NOT('[1]Changes to the template'!$D1<>"Parent")))),'[1]Changes to the template'!$B1<>"")),1=1)),1=1)

Sheet Sheet1
D13: 50的asin | J13: 500 | K13: 0.03 | L13: 700 | M13: 0.05 | N13: 1200 | O13: 0.08
B14: S/SS 级别产品则 * 2 否则 *1 | C14: 级别 | H14: purchasable_offer[marketplace_id=ATVPDKIKX0DER][audience=B2B]#1.our_price#1.schedule#1.value_with_tax | I14: purchasable_offer[marketplace_id=ATVPDKIKX0DER][audience=B2B]#1.quantity_discount_plan#1.schedule#1.discount_type | J14: purchasable_offer[marketplace_id=ATVPDKIKX0DER][audience=B2B]#1.quantity_discount_plan#1.schedule#1.levels#1.lower_bound | K14: purchasable_offer[marketplace_id=ATVPDKIKX0DER][audience=B2B]#1.quantity_discount_plan#1.schedule#1.levels#1.value | L14: purchasable_offer[marketplace_id=ATVPDKIKX0DER][audience=B2B]#1.quantity_discount_plan#1.schedule#1.levels#2.lower_bound | M14: purchasable_offer[marketplace_id=ATVPDKIKX0DER][audience=B2B]#1.quantity_discount_plan#1.schedule#1.levels#2.value | N14: purchasable_offer[marketplace_id=ATVPDKIKX0DER][audience=B2B]#1.quantity_discount_plan#1.schedule#1.levels#3.lower_bound | O14: purchasable_offer[marketplace_id=ATVPDKIKX0DER][audience=B2B]#1.quantity_discount_plan#1.schedule#1.levels#3.value | P14: purchasable_offer[marketplace_id=ATVPDKIKX0DER][audience=B2B]#1.quantity_discount_plan#1.schedule#1.levels#4.lower_bound | Q14: purchasable_offer[marketplace_id=ATVPDKIKX0DER][audience=B2B]#1.quantity_discount_plan#1.schedule#1.levels#4.value | R14: purchasable_offer[marketplace_id=ATVPDKIKX0DER][audience=B2B]#1.quantity_discount_plan#1.schedule#1.levels#5.lower_bound | S14: purchasable_offer[marketplace_id=ATVPDKIKX0DER][audience=B2B]#1.quantity_discount_plan#1.schedule#1.levels#5.value
A15: 2 | B15: =IF(OR(VLOOKUP(D15,Sheet4!$F$9:$G$245,2,0)="SS",VLOOKUP(D15,Sheet4!$F$9:$G$245,2,0)="S"),2,1) -> 1 | C15: =VLOOKUP(D15,Sheet4!$F$9:$G$245,2,0) -> P | D15: B0DTP8B4FZ | E15: =VLOOKUP(D15,'50库存'!$C$2:$D$313,2,0) -> 50US-MaiGanYaZi-013 | F15: =VLOOKUP(E15,'50库存'!$D$2:$U$313,18,0) -> 25.74 | G15: =COUNTIF('50库存'!$C$2:$C$313,D15) -> 1 | H15: =VLOOKUP(D15,'50库存'!$C$2:$U$313,19,0) -> 25.74 | I15: Percent | J15: =CEILING($J$13*B15/H15,1) -> 20 | K15: 3 | L15: =CEILING($L$13*B15/H15,1) -> 28 | M15: 5 | N15: =CEILING($N$13*B15/H15,1) -> 47 | O15: 8
A16: 1 | B16: =IF(OR(VLOOKUP(D16,Sheet4!$F$9:$G$245,2,0)="SS",VLOOKUP(D16,Sheet4!$F$9:$G$245,2,0)="S"),2,1) -> 1 | C16: =VLOOKUP(D16,Sheet4!$F$9:$G$245,2,0) -> P | D16: B0DTP4VV5V | E16: =VLOOKUP(D16,'50库存'!$C$2:$D$313,2,0) -> 50US-MaiGanYaZi-005 | F16: =VLOOKUP(E16,'50库存'!$D$2:$U$313,18,0) -> 29.99 | G16: =COUNTIF('50库存'!$C$2:$C$313,D16) -> 1 | H16: =VLOOKUP(D16,'50库存'!$C$2:$U$313,19,0) -> 29.99 | I16: Percent | J16: =CEILING($J$13*B16/H16,1) -> 17 | K16: 3 | L16: =CEILING($L$13*B16/H16,1) -> 24 | M16: 5 | N16: =CEILING($N$13*B16/H16,1) -> 41 | O16: 8
B17: =IF(OR(VLOOKUP(D17,Sheet4!$F$9:$G$245,2,0)="SS",VLOOKUP(D17,Sheet4!$F$9:$G$245,2,0)="S"),2,1) -> 1 | C17: =VLOOKUP(D17,Sheet4!$F$9:$G$245,2,0) -> P | D17: B0C7G7W43V | E17: =VLOOKUP(D17,'50库存'!$C$2:$D$313,2,0) -> 50US-MaoCiBabyBall001 | F17: =VLOOKUP(E17,'50库存'!$D$2:$U$313,18,0) -> 19.99 | G17: =COUNTIF('50库存'!$C$2:$C$313,D17) -> 1 | H17: =VLOOKUP(D17,'50库存'!$C$2:$U$313,19,0) -> 19.99 | I17: Percent | J17: =CEILING($J$13*B17/H17,1) -> 26 | K17: 3 | L17: =CEILING($L$13*B17/H17,1) -> 36 | M17: 5 | N17: =CEILING($N$13*B17/H17,1) -> 61 | O17: 8
B18: =IFERROR(IF(OR(VLOOKUP(D18,Sheet4!$F$9:$G$245,2,0)="SS",VLOOKUP(D18,Sheet4!$F$9:$G$245,2,0)="S"),2,1),1) -> 1 | C18: =VLOOKUP(D18,Sheet4!$F$9:$G$245,2,0) -> #N/A | D18: B0C7G9L4GD | E18: =VLOOKUP(D18,'50库存'!$C$2:$D$313,2,0) -> 50US-MaoCiBabyBall002 | F18: =VLOOKUP(E18,'50库存'!$D$2:$U$313,18,0) -> 18.99 | G18: =COUNTIF('50库存'!$C$2:$C$313,D18) -> 1 | H18: =VLOOKUP(D18,'50库存'!$C$2:$U$313,19,0) -> 18.99 | I18: Percent | J18: =CEILING($J$13*B18/H18,1) -> 27 | K18: 3 | L18: =CEILING($L$13*B18/H18,1) -> 37 | M18: 5 | N18: =CEILING($N$13*B18/H18,1) -> 64 | O18: 8
B19: =IFERROR(IF(OR(VLOOKUP(D19,Sheet4!$F$9:$G$245,2,0)="SS",VLOOKUP(D19,Sheet4!$F$9:$G$245,2,0)="S"),2,1),1) -> 1 | C19: =VLOOKUP(D19,Sheet4!$F$9:$G$245,2,0) -> P | D19: B0CCJKDDLG | E19: 50Fengrenji-WhiteNEW01 | F19: =VLOOKUP(E19,'50库存'!$D$2:$U$313,18,0) -> 43.37 | G19: =COUNTIF('50库存'!$C$2:$C$313,D19) -> 3 | H19: =VLOOKUP(E19,'50库存'!$D$2:$U$313,18,0) -> 43.37 | I19: Percent | J19: =CEILING($J$13*B19/H19,1) -> 12 | K19: 3 | L19: =CEILING($L$13*B19/H19,1) -> 17 | M19: 5 | N19: =CEILING($N$13*B19/H19,1) -> 28 | O19: 8
B20: =IFERROR(IF(OR(VLOOKUP(D20,Sheet4!$F$9:$G$245,2,0)="SS",VLOOKUP(D20,Sheet4!$F$9:$G$245,2,0)="S"),2,1),1) -> 1 | C20: =VLOOKUP(D20,Sheet4!$F$9:$G$245,2,0) -> P | D20: B0CCJKDDLG | E20: 50US-FengRenJi202-new | F20: =VLOOKUP(E20,'50库存'!$D$2:$U$313,18,0) -> 43.39 | H20: =VLOOKUP(E20,'50库存'!$D$2:$U$313,18,0) -> 43.39 | I20: Percent | J20: =CEILING($J$13*B20/H20,1) -> 12 | K20: 3 | L20: =CEILING($L$13*B20/H20,1) -> 17 | M20: 5 | N20: =CEILING($N$13*B20/H20,1) -> 28 | O20: 8
B21: =IFERROR(IF(OR(VLOOKUP(D21,Sheet4!$F$9:$G$245,2,0)="SS",VLOOKUP(D21,Sheet4!$F$9:$G$245,2,0)="S"),2,1),1) -> 1 | C21: =VLOOKUP(D21,Sheet4!$F$9:$G$245,2,0) -> P | D21: B0CCJKDDLG | E21: FRenJ-White 002 | F21: =VLOOKUP(E21,'50库存'!$D$2:$U$313,18,0) -> 0 | H21: =VLOOKUP(E21,'50库存'!$D$2:$U$313,18,0) -> 0 | I21: Percent | J21: =CEILING($J$13*B21/H21,1) -> #DIV/0! | K21: 3 | L21: =CEILING($L$13*B21/H21,1) -> #DIV/0! | M21: 5 | N21: =CEILING($N$13*B21/H21,1) -> #DIV/0! | O21: 8
B22: =IFERROR(IF(OR(VLOOKUP(D22,Sheet4!$F$9:$G$245,2,0)="SS",VLOOKUP(D22,Sheet4!$F$9:$G$245,2,0)="S"),2,1),1) -> 1 | C22: =VLOOKUP(D22,Sheet4!$F$9:$G$245,2,0) -> #N/A | D22: B0CCJKFGGG | E22: WhiteFengrenjiNew02 | F22: =VLOOKUP(E22,'50库存'!$D$2:$U$313,18,0) -> 43.99 | G22: =COUNTIF('50库存'!$C$2:$C$313,D22) -> 2 | H22: =VLOOKUP(E22,'50库存'!$D$2:$U$313,18,0) -> 43.99 | I22: Percent | J22: =CEILING($J$13*B22/H22,1) -> 12 | K22: 3 | L22: =CEILING($L$13*B22/H22,1) -> 16 | M22: 5 | N22: =CEILING($N$13*B22/H22,1) -> 28 | O22: 8
B23: =IFERROR(IF(OR(VLOOKUP(D23,Sheet4!$F$9:$G$245,2,0)="SS",VLOOKUP(D23,Sheet4!$F$9:$G$245,2,0)="S"),2,1),1) -> 1 | C23: =VLOOKUP(D23,Sheet4!$F$9:$G$245,2,0) -> #N/A | D23: B0CCJKFGGG | E23: FRenJ-White 004 | F23: =VLOOKUP(E23,'50库存'!$D$2:$U$313,18,0) -> 0 | H23: =VLOOKUP(E23,'50库存'!$D$2:$U$313,18,0) -> 0 | I23: Percent | J23: =CEILING($J$13*B23/H23,1) -> #DIV/0! | K23: 3 | L23: =CEILING($L$13*B23/H23,1) -> #DIV/0! | M23: 5 | N23: =CEILING($N$13*B23/H23,1) -> #DIV/0! | O23: 8
B24: =IFERROR(IF(OR(VLOOKUP(D24,Sheet4!$F$9:$G$245,2,0)="SS",VLOOKUP(D24,Sheet4!$F$9:$G$245,2,0)="S"),2,1),1) -> 1 | C24: =VLOOKUP(D24,Sheet4!$F$9:$G$245,2,0) -> A | D24: B0DTTBGYWW | E24: =VLOOKUP(D24,'50库存'!$C$2:$D$313,2,0) -> 50US-GenSuiYa-003 | F24: =VLOOKUP(E24,'50库存'!$D$2:$U$313,18,0) -> 39.99 | G24: =COUNTIF('50库存'!$C$2:$C$313,D24) -> 1 | H24: =VLOOKUP(E24,'50库存'!$D$2:$U$313,18,0) -> 39.99 | I24: Percent | J24: =CEILING($J$13*B24/H24,1) -> 13 | K24: 3 | L24: =CEILING($L$13*B24/H24,1) -> 18 | M24: 5 | N24: =CEILING($N$13*B24/H24,1) -> 31 | O24: 8
B25: =IFERROR(IF(OR(VLOOKUP(D25,Sheet4!$F$9:$G$245,2,0)="SS",VLOOKUP(D25,Sheet4!$F$9:$G$245,2,0)="S"),2,1),1) -> 1 | C25: =VLOOKUP(D25,Sheet4!$F$9:$G$245,2,0) -> A | D25: B0DTT3NTLG | E25: =VLOOKUP(D25,'50库存'!$C$2:$D$313,2,0) -> 50US-GenSuiYa-004 | F25: =VLOOKUP(E25,'50库存'!$D$2:$U$313,18,0) -> 39.99 | G25: =COUNTIF('50库存'!$C$2:$C$313,D25) -> 1 | H25: =VLOOKUP(E25,'50库存'!$D$2:$U$313,18,0) -> 39.99 | I25: Percent | J25: =CEILING($J$13*B25/H25,1) -> 13 | K25: 3 | L25: =CEILING($L$13*B25/H25,1) -> 18 | M25: 5 | N25: =CEILING($N$13*B25/H25,1) -> 31 | O25: 8
B26: =IFERROR(IF(OR(VLOOKUP(D26,Sheet4!$F$9:$G$245,2,0)="SS",VLOOKUP(D26,Sheet4!$F$9:$G$245,2,0)="S"),2,1),1) -> 1 | C26: =VLOOKUP(D26,Sheet4!$F$9:$G$245,2,0) -> A | D26: B0DTT4GNWW | E26: =VLOOKUP(D26,'50库存'!$C$2:$D$313,2,0) -> 50US-GenSuiYa-005 | F26: =VLOOKUP(E26,'50库存'!$D$2:$U$313,18,0) -> 36.99 | G26: =COUNTIF('50库存'!$C$2:$C$313,D26) -> 1 | H26: =VLOOKUP(E26,'50库存'!$D$2:$U$313,18,0) -> 36.99 | I26: Percent | J26: =CEILING($J$13*B26/H26,1) -> 14 | K26: 3 | L26: =CEILING($L$13*B26/H26,1) -> 19 | M26: 5 | N26: =CEILING($N$13*B26/H26,1) -> 33 | O26: 8
B27: =IFERROR(IF(OR(VLOOKUP(D27,Sheet4!$F$9:$G$245,2,0)="SS",VLOOKUP(D27,Sheet4!$F$9:$G$245,2,0)="S"),2,1),1) -> 1 | C27: =VLOOKUP(D27,Sheet4!$F$9:$G$245,2,0) -> A | D27: B0DTT8SK6H | E27: =VLOOKUP(D27,'50库存'!$C$2:$D$313,2,0) -> 50US-GenSuiYa-006 | F27: =VLOOKUP(E27,'50库存'!$D$2:$U$313,18,0) -> 35.99 | G27: =COUNTIF('50库存'!$C$2:$C$313,D27) -> 1 | H27: =VLOOKUP(E27,'50库存'!$D$2:$U$313,18,0) -> 35.99 | I27: Percent | J27: =CEILING($J$13*B27/H27,1) -> 14 | K27: 3 | L27: =CEILING($L$13*B27/H27,1) -> 20 | M27: 5 | N27: =CEILING($N$13*B27/H27,1) -> 34 | O27: 8
B28: =IFERROR(IF(OR(VLOOKUP(D28,Sheet4!$F$9:$G$245,2,0)="SS",VLOOKUP(D28,Sheet4!$F$9:$G$245,2,0)="S"),2,1),1) -> 1 | C28: =VLOOKUP(D28,Sheet4!$F$9:$G$245,2,0) -> A | D28: B0DYMGYWJ7 | E28: =VLOOKUP(D28,'50库存'!$C$2:$D$313,2,0) -> 50-3Ddongwupintu-Shizi1 | F28: =VLOOKUP(E28,'50库存'!$D$2:$U$313,18,0) -> 23.99 | G28: =COUNTIF('50库存'!$C$2:$C$313,D28) -> 1 | H28: =VLOOKUP(E28,'50库存'!$D$2:$U$313,18,0) -> 23.99 | I28: Percent | J28: =CEILING($J$13*B28/H28,1) -> 21 | K28: 3 | L28: =CEILING($L$13*B28/H28,1) -> 30 | M28: 5 | N28: =CEILING($N$13*B28/H28,1) -> 51 | O28: 8
B29: =IFERROR(IF(OR(VLOOKUP(D29,Sheet4!$F$9:$G$245,2,0)="SS",VLOOKUP(D29,Sheet4!$F$9:$G$245,2,0)="S"),2,1),1) -> 1 | C29: =VLOOKUP(D29,Sheet4!$F$9:$G$245,2,0) -> A | D29: B0DYN4HDJW | E29: =VLOOKUP(D29,'50库存'!$C$2:$D$313,2,0) -> 50-3Ddongwupintu-Lu1 | F29: =VLOOKUP(E29,'50库存'!$D$2:$U$313,18,0) -> 23.99 | G29: =COUNTIF('50库存'!$C$2:$C$313,D29) -> 1 | H29: =VLOOKUP(E29,'50库存'!$D$2:$U$313,18,0) -> 23.99 | I29: Percent | J29: =CEILING($J$13*B29/H29,1) -> 21 | K29: 3 | L29: =CEILING($L$13*B29/H29,1) -> 30 | M29: 5 | N29: =CEILING($N$13*B29/H29,1) -> 51 | O29: 8
B30: =IFERROR(IF(OR(VLOOKUP(D30,Sheet4!$F$9:$G$245,2,0)="SS",VLOOKUP(D30,Sheet4!$F$9:$G$245,2,0)="S"),2,1),1) -> 1 | C30: =VLOOKUP(D30,Sheet4!$F$9:$G$245,2,0) -> A | D30: B0FHH5Q86M | E30: =VLOOKUP(D30,'50库存'!$C$2:$D$313,2,0) -> G502GuYuKaChe001 | F30: =VLOOKUP(E30,'50库存'!$D$2:$U$313,18,0) -> 22.99 | G30: =COUNTIF('50库存'!$C$2:$C$313,D30) -> 1 | H30: =VLOOKUP(E30,'50库存'!$D$2:$U$313,18,0) -> 22.99 | I30: Percent | J30: =CEILING($J$13*B30/H30,1) -> 22 | K30: 3 | L30: =CEILING($L$13*B30/H30,1) -> 31 | M30: 5 | N30: =CEILING($N$13*B30/H30,1) -> 53 | O30: 8
B31: =IFERROR(IF(OR(VLOOKUP(D31,Sheet4!$F$9:$G$245,2,0)="SS",VLOOKUP(D31,Sheet4!$F$9:$G$245,2,0)="S"),2,1),1) -> 1 | C31: =VLOOKUP(D31,Sheet4!$F$9:$G$245,2,0) -> A | D31: B0FHHC21LG | E31: =VLOOKUP(D31,'50库存'!$C$2:$D$313,2,0) -> G502GuYuKaChe002 | F31: =VLOOKUP(E31,'50库存'!$D$2:$U$313,18,0) -> 22.99 | G31: =COUNTIF('50库存'!$C$2:$C$313,D31) -> 1 | H31: =VLOOKUP(E31,'50库存'!$D$2:$U$313,18,0) -> 22.99 | I31: Percent | J31: =CEILING($J$13*B31/H31,1) -> 22 | K31: 3 | L31: =CEILING($L$13*B31/H31,1) -> 31 | M31: 5 | N31: =CEILING($N$13*B31/H31,1) -> 53 | O31: 8
B32: =IFERROR(IF(OR(VLOOKUP(D32,Sheet4!$F$9:$G$245,2,0)="SS",VLOOKUP(D32,Sheet4!$F$9:$G$245,2,0)="S"),2,1),1) -> 1 | C32: =VLOOKUP(D32,Sheet4!$F$9:$G$245,2,0) -> A | D32: B0FHHC11GJ | E32: =VLOOKUP(D32,'50库存'!$C$2:$D$313,2,0) -> G503GuYuWaJueJi001 | F32: =VLOOKUP(E32,'50库存'!$D$2:$U$313,18,0) -> 23.99 | G32: =COUNTIF('50库存'!$C$2:$C$313,D32) -> 1 | H32: =VLOOKUP(E32,'50库存'!$D$2:$U$313,18,0) -> 23.99 | I32: Percent | J32: =CEILING($J$13*B32/H32,1) -> 21 | K32: 3 | L32: =CEILING($L$13*B32/H32,1) -> 30 | M32: 5 | N32: =CEILING($N$13*B32/H32,1) -> 51 | O32: 8
B33: =IFERROR(IF(OR(VLOOKUP(D33,Sheet4!$F$9:$G$245,2,0)="SS",VLOOKUP(D33,Sheet4!$F$9:$G$245,2,0)="S"),2,1),1) -> 1 | C33: =VLOOKUP(D33,Sheet4!$F$9:$G$245,2,0) -> A | D33: B0FHH5PQ4H | E33: =VLOOKUP(D33,'50库存'!$C$2:$D$313,2,0) -> G503GuYuWaJueJi002 | F33: =VLOOKUP(E33,'50库存'!$D$2:$U$313,18,0) -> 22.99 | G33: =COUNTIF('50库存'!$C$2:$C$313,D33) -> 1 | H33: =VLOOKUP(E33,'50库存'!$D$2:$U$313,18,0) -> 22.99 | I33: Percent | J33: =CEILING($J$13*B33/H33,1) -> 22 | K33: 3 | L33: =CEILING($L$13*B33/H33,1) -> 31 | M33: 5 | N33: =CEILING($N$13*B33/H33,1) -> 53 | O33: 8
B34: =IFERROR(IF(OR(VLOOKUP(D34,Sheet4!$F$9:$G$245,2,0)="SS",VLOOKUP(D34,Sheet4!$F$9:$G$245,2,0)="S"),2,1),1) -> 1 | C34: =VLOOKUP(D34,Sheet4!$F$9:$G$245,2,0) -> #N/A | D34: B0GCH6J851 | E34: G505Guyuhuoche | F34: =VLOOKUP(E34,'50库存'!$D$2:$U$313,18,0) -> 0 | G34: =COUNTIF('50库存'!$C$2:$C$313,D34) -> 2 | H34: =VLOOKUP(E34,'50库存'!$D$2:$U$313,18,0) -> 0 | I34: Percent | J34: =CEILING($J$13*B34/H34,1) -> #DIV/0! | K34: 3 | L34: =CEILING($L$13*B34/H34,1) -> #DIV/0! | M34: 5 | N34: =CEILING($N$13*B34/H34,1) -> #DIV/0! | O34: 8
B35: =IFERROR(IF(OR(VLOOKUP(D35,Sheet4!$F$9:$G$245,2,0)="SS",VLOOKUP(D35,Sheet4!$F$9:$G$245,2,0)="S"),2,1),1) -> 1 | C35: =VLOOKUP(D35,Sheet4!$F$9:$G$245,2,0) -> #N/A | D35: B0GCH6J851 | E35: 50US-G501GuYuHuoChe | F35: =VLOOKUP(E35,'50库存'!$D$2:$U$313,18,0) -> 19.99 | G35: =COUNTIF('50库存'!$C$2:$C$313,D35) -> 2 | H35: =VLOOKUP(E35,'50库存'!$D$2:$U$313,18,0) -> 19.99 | I35: Percent | J35: =CEILING($J$13*B35/H35,1) -> 26 | K35: 3 | L35: =CEILING($L$13*B35/H35,1) -> 36 | M35: 5 | N35: =CEILING($N$13*B35/H35,1) -> 61 | O35: 8
B36: =IFERROR(IF(OR(VLOOKUP(D36,Sheet4!$F$9:$G$245,2,0)="SS",VLOOKUP(D36,Sheet4!$F$9:$G$245,2,0)="S"),2,1),1) -> 1 | C36: =VLOOKUP(D36,Sheet4!$F$9:$G$245,2,0) -> #N/A | D36: B0GCHH67CH | E36: =VLOOKUP(D36,'50库存'!$C$2:$D$313,2,0) -> G504Guyuhuoche | F36: =VLOOKUP(E36,'50库存'!$D$2:$U$313,18,0) -> 20.99 | G36: =COUNTIF('50库存'!$C$2:$C$313,D36) -> 1 | H36: =VLOOKUP(E36,'50库存'!$D$2:$U$313,18,0) -> 20.99 | I36: Percent | J36: =CEILING($J$13*B36/H36,1) -> 24 | K36: 3 | L36: =CEILING($L$13*B36/H36,1) -> 34 | M36: 5 | N36: =CEILING($N$13*B36/H36,1) -> 58 | O36: 8
B37: =IFERROR(IF(OR(VLOOKUP(D37,Sheet4!$F$9:$G$245,2,0)="SS",VLOOKUP(D37,Sheet4!$F$9:$G$245,2,0)="S"),2,1),1) -> 1 | C37: =VLOOKUP(D37,Sheet4!$F$9:$G$245,2,0) -> #N/A | D37: B0FHH5PNNZ | E37: 50US-G505GuYuZhiShengJi | F37: =VLOOKUP(E37,'50库存'!$D$2:$U$313,18,0) -> 0 | G37: =COUNTIF('50库存'!$C$2:$C$313,D37) -> 2 | H37: =VLOOKUP(E37,'50库存'!$D$2:$U$313,18,0) -> 0 | I37: Percent | J37: =CEILING($J$13*B37/H37,1) -> #DIV/0! | K37: 3 | L37: =CEILING($L$13*B37/H37,1) -> #DIV/0! | M37: 5 | N37: =CEILING($N$13*B37/H37,1) -> #DIV/0! | O37: 8
D38: B0FHH5PNNZ | E38: G501Guyuhuoche | F38: =VLOOKUP(E38,'50库存'!$D$2:$U$313,18,0) -> 0 | G38: =COUNTIF('50库存'!$C$2:$C$313,D38) -> 2 | H38: =VLOOKUP(E38,'50库存'!$D$2:$U$313,18,0) -> 0 | I38: Percent | J38: =CEILING($J$13*B38/H38,1) -> #DIV/0! | K38: 3 | L38: =CEILING($L$13*B38/H38,1) -> #DIV/0! | M38: 5 | N38: =CEILING($N$13*B38/H38,1) -> #DIV/0! | O38: 8
B39: =IFERROR(IF(OR(VLOOKUP(D39,Sheet4!$F$9:$G$245,2,0)="SS",VLOOKUP(D39,Sheet4!$F$9:$G$245,2,0)="S"),2,1),1) -> 1 | C39: =VLOOKUP(D39,Sheet4!$F$9:$G$245,2,0) -> A | D39: B0FG6W44P5 | E39: =VLOOKUP(D39,'50库存'!$C$2:$D$313,2,0) -> 50US-HanBaoJi-002 | F39: =VLOOKUP(E39,'50库存'!$D$2:$U$313,18,0) -> 36.99 | G39: =COUNTIF('50库存'!$C$2:$C$313,D39) -> 1 | H39: =VLOOKUP(E39,'50库存'!$D$2:$U$313,18,0) -> 36.99 | I39: Percent | J39: =CEILING($J$13*B39/H39,1) -> 14 | K39: 3 | L39: =CEILING($L$13*B39/H39,1) -> 19 | M39: 5 | N39: =CEILING($N$13*B39/H39,1) -> 33 | O39: 8
B40: =IFERROR(IF(OR(VLOOKUP(D40,Sheet4!$F$9:$G$245,2,0)="SS",VLOOKUP(D40,Sheet4!$F$9:$G$245,2,0)="S"),2,1),1) -> 1 | C40: =VLOOKUP(D40,Sheet4!$F$9:$G$245,2,0) -> A | D40: B0FG73GKBG | E40: =VLOOKUP(D40,'50库存'!$C$2:$D$313,2,0) -> 50US-HanBaoJi-003 | F40: =VLOOKUP(E40,'50库存'!$D$2:$U$313,18,0) -> 38.99 | G40: =COUNTIF('50库存'!$C$2:$C$313,D40) -> 1 | H40: =VLOOKUP(E40,'50库存'!$D$2:$U$313,18,0) -> 38.99 | I40: Percent | J40: =CEILING($J$13*B40/H40,1) -> 13 | K40: 3 | L40: =CEILING($L$13*B40/H40,1) -> 18 | M40: 5 | N40: =CEILING($N$13*B40/H40,1) -> 31 | O40: 8
B41: =IFERROR(IF(OR(VLOOKUP(D41,Sheet4!$F$9:$G$245,2,0)="SS",VLOOKUP(D41,Sheet4!$F$9:$G$245,2,0)="S"),2,1),1) -> 1 | C41: =VLOOKUP(D41,Sheet4!$F$9:$G$245,2,0) -> P | D41: B0FHKLCG68 | E41: =VLOOKUP(D41,'50库存'!$C$2:$D$313,2,0) -> YinErTanSheTouLanJi-0001 | F41: =VLOOKUP(E41,'50库存'!$D$2:$U$313,18,0) -> 29.99 | G41: =COUNTIF('50库存'!$C$2:$C$313,D41) -> 1 | H41: =VLOOKUP(E41,'50库存'!$D$2:$U$313,18,0) -> 29.99 | I41: Percent | J41: =CEILING($J$13*B41/H41,1) -> 17 | K41: 3 | L41: =CEILING($L$13*B41/H41,1) -> 24 | M41: 5 | N41: =CEILING($N$13*B41/H41,1) -> 41 | O41: 8
B42: =IFERROR(IF(OR(VLOOKUP(D42,Sheet4!$F$9:$G$245,2,0)="SS",VLOOKUP(D42,Sheet4!$F$9:$G$245,2,0)="S"),2,1),1) -> 1 | C42: =VLOOKUP(D42,Sheet4!$F$9:$G$245,2,0) -> #N/A | D42: B0F13S45L4 | E42: =VLOOKUP(D42,'50库存'!$C$2:$D$313,2,0) -> 50US-DuiDieKongLong-003 | F42: =VLOOKUP(E42,'50库存'!$D$2:$U$313,18,0) -> 0 | G42: =COUNTIF('50库存'!$C$2:$C$313,D42) -> 1 | H42: =VLOOKUP(E42,'50库存'!$D$2:$U$313,18,0) -> 0 | I42: Percent | J42: =CEILING($J$13*B42/H42,1) -> #DIV/0! | K42: 3 | L42: =CEILING($L$13*B42/H42,1) -> #DIV/0! | M42: 5 | N42: =CEILING($N$13*B42/H42,1) -> #DIV/0! | O42: 8
B43: =IFERROR(IF(OR(VLOOKUP(D43,Sheet4!$F$9:$G$245,2,0)="SS",VLOOKUP(D43,Sheet4!$F$9:$G$245,2,0)="S"),2,1),1) -> 1 | C43: =VLOOKUP(D43,Sheet4!$F$9:$G$245,2,0) -> #N/A | D43: B0FMXV3JBC | E43: =VLOOKUP(D43,'50库存'!$C$2:$D$313,2,0) -> 50US-DuiDieKongLong-007 | F43: =VLOOKUP(E43,'50库存'!$D$2:$U$313,18,0) -> 36.99 | G43: =COUNTIF('50库存'!$C$2:$C$313,D43) -> 1 | H43: =VLOOKUP(E43,'50库存'!$D$2:$U$313,18,0) -> 36.99 | I43: Percent | J43: =CEILING($J$13*B43/H43,1) -> 14 | K43: 3 | L43: =CEILING($L$13*B43/H43,1) -> 19 | M43: 5 | N43: =CEILING($N$13*B43/H43,1) -> 33 | O43: 8
B44: =IFERROR(IF(OR(VLOOKUP(D44,Sheet4!$F$9:$G$245,2,0)="SS",VLOOKUP(D44,Sheet4!$F$9:$G$245,2,0)="S"),2,1),1) -> 1 | C44: =VLOOKUP(D44,Sheet4!$F$9:$G$245,2,0) -> #N/A | D44: B0GJWXPW57，50US-RuanDanTankFaSheTou-01 | F44: 39.99 | G44: =COUNTIF('50库存'!$C$2:$C$313,D44) -> 0 | H44: 39.99 | I44: Percent | J44: =CEILING($J$13*B44/H44,1) -> 13 | K44: 3 | L44: =CEILING($L$13*B44/H44,1) -> 18 | M44: 5 | N44: =CEILING($N$13*B44/H44,1) -> 31 | O44: 8
D48: only-value
D49: B0DTP8B4FZ | E49: 50US-MaiGanYaZi-013 | F49: 25.74 | G49: 1 | H49: 25.74 | I49: Percent | J49: 20 | K49: 3 | L49: 28 | M49: 5 | N49: 47 | O49: 8
D50: B0DTP4VV5V | E50: 50US-MaiGanYaZi-005 | F50: 29.99 | G50: 1 | H50: 29.99 | I50: Percent | J50: 17 | K50: 3 | L50: 24 | M50: 5 | N50: 41 | O50: 8
D51: B0C7G7W43V | E51: 50US-MaoCiBabyBall001 | F51: 19.99 | G51: 1 | H51: 19.99 | I51: Percent | J51: 26 | K51: 3 | L51: 36 | M51: 5 | N51: 61 | O51: 8
D52: B0C7G9L4GD | E52: 50US-MaoCiBabyBall002 | F52: 18.99 | G52: 1 | H52: 18.99 | I52: Percent | J52: 27 | K52: 3 | L52: 37 | M52: 5 | N52: 64 | O52: 8
D53: B0CCJKDDLG | E53: 50Fengrenji-WhiteNEW01 | F53: 43.37 | G53: 3 | H53: 43.37 | I53: Percent | J53: 12 | K53: 3 | L53: 17 | M53: 5 | N53: 28 | O53: 8
D54: B0CCJKDDLG | E54: 50US-FengRenJi202-new | F54: 43.39 | H54: 43.39 | I54: Percent | J54: 12 | K54: 3 | L54: 17 | M54: 5 | N54: 28 | O54: 8
D55: B0CCJKDDLG | E55: FRenJ-White 002 | F55: 0 | H55: 0 | I55: Percent | J55: #DIV/0! | K55: 3 | L55: #DIV/0! | M55: 5 | N55: #DIV/0! | O55: 8
...

Sheet 50库存
A1: snapshot-date | B1: fnsku | C1: asin | D1: sku | E1: product-name | F1: condition | G1: available | H1: pending-removal-quantity | I1: inv-age-0-to-90-days | J1: inv-age-91-to-180-days | K1: inv-age-181-to-270-days | L1: inv-age-271-to-365-days | M1: inv-age-366-to-455-days | N1: inv-age-456-plus-days | O1: currency | P1: units-shipped-t7 | Q1: units-shipped-t30 | R1: units-shipped-t60 | S1: units-shipped-t90 | T1: alert | U1: your-price | V1: sales-price | W1: lowest-price-new-plus-shipping | X1: lowest-price-used | Y1: recommended-action | Z1: DEPRECATED healthy-inventory-level | AA1: recommended-sales-price | AB1: recommended-sale-duration-days | AC1: recommended-removal-quantity | AD1: estimated-cost-savings-of-recommended-actions | AE1: sell-through | AF1: item-volume | AG1: volume-unit-measurement | AH1: storage-type | AI1: storage-volume | AJ1: marketplace | AK1: product-group | AL1: sales-rank | AM1: days-of-supply | AN1: estimated-excess-quantity | AO1: weeks-of-cover-t30 | AP1: weeks-of-cover-t90 | AQ1: featuredoffer-price | AR1: sales-shipped-last-7-days | AS1: sales-shipped-last-30-days | AT1: sales-shipped-last-60-days | AU1: sales-shipped-last-90-days | AV1: inv-age-0-to-30-days | AW1: inv-age-31-to-60-days | AX1: inv-age-61-to-90-days | AY1: inv-age-181-to-330-days | AZ1: inv-age-331-to-365-days | BA1: estimated-storage-cost-next-month | BB1: inbound-quantity | BC1: inbound-working | BD1: inbound-shipped | BE1: inbound-received | BF1: no-sale-last-6-months | BG1: Total Reserved Quantity | BH1: unfulfillable-quantity | BI1: quantity-to-be-charged-ais-181-210-days | BJ1: estimated-ais-181-210-days | BK1: quantity-to-be-charged-ais-211-240-days | BL1: estimated-ais-211-240-days | BM1: quantity-to-be-charged-ais-241-270-days | BN1: estimated-ais-241-270-days | BO1: quantity-to-be-charged-ais-271-300-days | BP1: estimated-ais-271-300-days | BQ1: quantity-to-be-charged-ais-301-330-days | BR1: estimated-ais-301-330-days | BS1: quantity-to-be-charged-ais-331-365-days | BT1: estimated-ais-331-365-days | BU1: quantity-to-be-charged-ais-366-455-days | BV1: estimated-ais-366-455-days | BW1: quantity-to-be-charged-ais-456-plus-days | BX1: estimated-ais-456-plus-days | BY1: historical-days-of-supply | BZ1: fba-minimum-inventory-level | CA1: fba-inventory-level-health-status | CB1: Recommended ship-in quantity | CC1: Recommended ship-in date | CD1: Last updated date for Historical Days of Supply | CE1: Exempted from Low-Inventory-Level fee? | CF1: Low-Inventory-Level fee applied in current week? | CG1: Short term historical days of supply | CH1: Long term historical days of supply | CI1: Inventory age snapshot date | CJ1: Inventory Supply at FBA | CK1: Reserved FC Transfer | CL1: Reserved FC Processing | CM1: Reserved Customer Order | CN1: Reserved Staging | CO1: Total Days of Supply (including units from open shipments) | CP1: supplier | CQ1: is-seasonal-in-next-3-months | CR1: season-name | CS1: season-start-date | CT1: season-end-date
A2: 46188 | B2: X0042YZRY5 | C2: B0CQXJ37CQ | D2: NewSewingMachinePink 0001 | E2: Portable Sewing Machine for Beginners, Mini Electric Sewing Machine 12 Built-in Stitch Patterns, Light, 2 Speed with Foot Pedal & Sewing Kit, Household máquinas de coser for Kids Ages 8-12 | F2: New | G2: 33 | H2: 0 | I2: 20 | J2: 14 | K2: 0 | L2: 0 | M2: 0 | N2: 0 | O2: USD | P2: 3 | Q2: 10 | R2: 15 | S2: 22 | U2: 79.99 | V2: 49.99 | W2: 49.99 | X2: 0 | Y2: NoExcessInventory | AA2: 0 | AB2: 0 | AC2: 0 | AD2: 0 | AE2: 0.65 | AF2: 0.744874 | AG2: cubic feet | AH2: Standard | AI2: 24.580842 | AJ2: US | AK2: gl_home | AL2: 32209 | AM2: 100 | AN2: 0 | AO2: 14 | AP2: 21 | AQ2: 49.99 | AR2: 149.97 | AS2: 522.4 | AT2: 759.85 | AU2: 1097.28 | AV2: 18 | AW2: 2 | AX2: 0 | AY2: 0 | AZ2: 0 | BA2: 16.21 | BB2: 3 | BC2: 0 | BD2: 0 | BE2: 3 | BG2: 1 | BH2: 0 | BY2: 137.5 | BZ2: 38 | CA2: Low stock | CB2: 24 | CC2: 46193 | CD2: 46188 | CE2: Yes | CF2: No | CG2: 115.7 | CH2: 137.5 | CI2: 46186 | CJ2: 36 | CK2: 0 | CL2: 1 | CM2: 0 | CN2: 0 | CO2: 102 | CP2: unassigned | CQ2: N
A3: 46188 | B3: X004T1CKOB | C3: B0FHH5PQ4H | D3: G503GuYuWaJueJi002 | E3: ROHSCE Push and Go Friction Powered Toy Cars for Toddlers 1-3, Musical Cartoon Excavator Construction Vehicles, Baby Engineering Trucks for 1 2 3 Year Old Boys Girls, Birthday | F3: New | G3: 32 | H3: 0 | I3: 0 | J3: 32 | K3: 0 | L3: 0 | M3: 0 | N3: 0 | O3: USD | P3: 0 | Q3: 1 | R3: 2 | S3: 4 | T3: Low traffic | U3: 22.99 | V3: 15.49 | W3: 15.49 | X3: 0 | Y3: Create Outlet deal | AA3: 10.84 | AB3: 2 | AC3: 0 | AD3: 448.27 | AE3: 0.12 | AF3: 0.054246 | AG3: cubic feet | AH3: Standard | AI3: 1.735872 | AJ3: US | AK3: gl_toy | AL3: 598598 | AM3: 366 | AN3: 32 | AO3: 128 | AP3: 104 | AQ3: 15.49 | AR3: 0 | AS3: 15.49 | AT3: 31.81 | AU3: 63.53 | AV3: 0 | AW3: 0 | AX3: 0 | AY3: 0 | AZ3: 0 | BA3: 1.24 | BB3: 0 | BC3: 0 | BD3: 0 | BE3: 0 | BG3: 0 | BH3: 0 | BY3: 976 | BZ3: 3 | CA3: Excess | CD3: 46188 | CE3: Yes | CF3: No | CG3: 976 | CH3: 758 | CI3: 46186 | CJ3: 32 | CK3: 0 | CL3: 0 | CM3: 0 | CN3: 0 | CO3: 366 | CP3: unassigned | CQ3: N
A4: 46188 | B4: X0042Z3XE5 | C4: B0CQX71441 | D4: NewSewingMachineBlack 0002 | E4: Flying Banana Mini Sewing Machine for Beginners, Portable Electric Small Mending Machine with 12 Stitches, Foot Pedal, LED Light, 2 Speeds, Kids Sewing Kit for Boys & Girls 6-12 Years Old - White | F4: New | G4: 17 | H4: 0 | I4: 20 | J4: 3 | K4: 0 | L4: 0 | M4: 0 | N4: 0 | O4: USD | P4: 2 | Q4: 5 | R4: 14 | S4: 20 | U4: 89.99 | V4: 64.99 | W4: 64.99 | X4: 0 | Y4: NoRestockExcessActionRequired | AA4: 0 | AB4: 0 | AC4: 0 | AD4: 0 | AE4: 1.03 | AF4: 0.734919 | AG4: cubic feet | AH4: Standard | AI4: 12.493623 | AJ4: US | AK4: gl_home | AL4: 32209 | AM4: 185 | AN4: 0 | AO4: 47 | AP4: 38 | AQ4: 64.99 | AR4: 129.98 | AS4: 324.95 | AT4: 900.86 | AU4: 1320.8 | AV4: 19 | AW4: 0 | AX4: 1 | AY4: 0 | AZ4: 0 | BA4: 32.42 | BB4: 42 | BC4: 0 | BD4: 42 | BE4: 0 | BG4: 6 | BH4: 0 | BY4: 117 | BZ4: 14 | CA4: Healthy | CD4: 46188 | CE4: Yes | CF4: No | CG4: 117 | CH4: 75.1 | CI4: 46186 | CJ4: 59 | CK4: 0 | CL4: 0 | CM4: 0 | CN4: 6 | CO4: 189 | CP4: unassigned | CQ4: N
A5: 46188 | B5: X002LTO7VR | C5: B07SRSJZSL | D5: 6JianQiuUs-5001 | E5: ROHSCE Sensory Balls for Baby Sensory Baby Toys 6 to 12 Months for Toddlers 1-3, Bright Color Textured Multi Soft Ball Gift Sets, Montessori Toys for Babies 6-12 Months Infant Toys (6 Pack) | F5: New | G5: 3462 | H5: 0 | I5: 5400 | J5: 0 | K5: 0 | L5: 0 | M5: 0 | N5: 0 | O5: USD | P5: 495 | Q5: 1928 | R5: 3671 | S5: 5598 | U5: 15.99 | V5: 0 | W5: 15.99 | X5: 0 | Y5: NoRestockExcessActionRequired | AA5: 0 | AB5: 0 | AC5: 0 | AD5: 0 | AE5: 1.89 | AF5: 0.08017 | AG5: cubic feet | AH5: Standard | AI5: 277.54854 | AJ5: US | AK5: gl_toy | AL5: 2409 | AM5: 95 | AN5: 0 | AO5: 22 | AP5: 24 | AQ5: 15.99 | AR5: 7910.57 | AS5: 30884.24 | AT5: 58227.21 | AU5: 88067.54 | AV5: 5400 | AW5: 0 | AX5: 0 | AY5: 0 | AZ5: 0 | BA5: 296.7 | BB5: 7301 | BC5: 3744 | BD5: 3216 | BE5: 341 | BG5: 1418 | BH5: 5 | BY5: 59.4 | BZ5: 3707 | CA5: Healthy | CD5: 46188 | CE5: No | CF5: No | CG5: 59.4 | CH5: 41.1 | CI5: 46185 | CJ5: 11575 | CK5: 812 | CL5: 156 | CM5: 13 | CN5: 1249 | CO5: 170 | CQ5: N
A6: 46188 | B6: X0046NX1NV | C6: B0C6T332PH | D6: 50-huangsepenshuihuojian-2PH | E6: ROHSCE Water Rocket Sprinkler for Kids, Outdoor Sprinkler Rocket Launcher Toy for Backyard, Summer Water Toys for Kids Ages 3-12, Fun Water Powered Rocket Toy (Yellow-1) | G6: 0 | H6: -1 | O6: USD | U6: 0 | V6: 0 | W6: 0 | X6: 0 | Y6: NoRestockExcessActionRequired | AB6: 0 | AC6: 0 | AE6: -1 | AH6: Standard | AJ6: US | AK6: gl_toy | AM6: 0 | AN6: 0 | AQ6: 26.99 | AY6: 0 | BB6: 0 | BC6: 0 | BD6: 0 | BE6: 0 | BG6: 0 | BH6: 0 | CJ6: 0 | CK6: 0 | CL6: 0 | CM6: 0 | CN6: 0 | CO6: 0 | CP6: unassigned | CQ6: N
A7: 46188 | B7: X005554ZWP | C7: B0GTL46L4V | D7: 50US-trainmangluban | E7: ROHSCE Baby Activity Cube Toys 12-18 Months, Montessori Musical Train with Lights & Sounds, Shape Sorter Busy Cube, Multifunctional Learning Toys for Toddlers 1-3 Boys Girls | F7: New | G7: 0 | H7: -1 | O7: USD | U7: 65.99 | V7: 0 | W7: 0 | X7: 0 | Y7: Edit listing | AB7: 0 | AC7: 0 | AE7: -1 | AH7: Standard | AJ7: US | AK7: gl_toy | AN7: 0 | AY7: 0 | BB7: 15 | BC7: 15 | BD7: 0 | BE7: 0 | BG7: 0 | BH7: 0 | CJ7: 15 | CK7: 0 | CL7: 0 | CM7: 0 | CN7: 0 | CP7: unassigned | CQ7: N
A8: 46188 | B8: X004ML2I7R | C8: B0F192Z9C9 | D8: 50US-YingErYongQuan-003 | E8: Baby Pool Float with Removable Canopy Baby Float,Friendly Material Swim Trainer for Toddler Boys Girls,Babies Toy | G8: 0 | H8: -1 | O8: USD | U8: 0 | V8: 0 | W8: 0 | X8: 0 | Y8: NoRestockExcessActionRequired | AB8: 0 | AC8: 0 | AE8: -1 | AH8: Other | AJ8: US | AK8: gl_outdoors | AN8: 0 | AY8: 0 | BB8: 0 | BG8: 0 | BH8: 0 | CJ8: 0 | CK8: 0 | CL8: 0 | CM8: 0 | CN8: 0 | CP8: unassigned | CQ8: N
A9: 46188 | B9: X0051COV53 | C9: B0GSPQCM17 | D9: 50US-BallsBlocks26PCS-01 | E9: ROHSCE 26PCS Textured Sensory Balls & Soft Silicone Building Blocks, Montessori Stacking Toy for Babies 6-12 Months, BPA-Free Infant Sensory Toys for Grasping & Early Learning | G9: 0 | H9: -1 | O9: USD | U9: 0 | V9: 0 | W9: 0 | X9: 0 | Y9: NoRestockExcessActionRequired | AB9: 0 | AC9: 0 | AE9: -1 | AH9: Other | AJ9: US | AK9: gl_toy | AN9: 0 | AY9: 0 | BB9: 0 | BG9: 0 | BH9: 0 | CJ9: 0 | CK9: 0 | CL9: 0 | CM9: 0 | CN9: 0 | CP9: unassigned | CQ9: N
A10: 46188 | B10: X002UKDWNB | C10: B0915H7J7Q | D10: FBA-YuLian- parent-0001 | E10: ROHSCE No Hooks Waffle Weave Mildew Resistant Shower Curtain with Snap in Removable Liner for Bathroom-Hotel Grade,Mesh Top Window, Machine Washable-72x72inch | G10: 0 | H10: -1 | O10: USD | U10: 0 | V10: 0 | W10: 0 | X10: 0 | Y10: NoRestockExcessActionRequired | AB10: 0 | AC10: 0 | AE10: -1 | AJ10: US | AK10: gl_home | AN10: 0 | AY10: 0 | BB10: 0 | BG10: 0 | BH10: 0 | CJ10: 0 | CK10: 0 | CL10: 0 | CM10: 0 | CN10: 0 | CP10: unassigned | CQ10: N
A11: 46188 | B11: X004MN5Z89 | C11: B0DTP55X8K | D11: 50US-MaiGanYaZi-004 | E11: ROHSCE Baby Bath Toys 6-12 Months, 9 Pcs Wheat Straw Sensory Balls & Ducks, No Hole Floating Toddler Bath Toys, for Boys & Girls 1-3, Textured Squeeze Stress Relief Montessori Set | F11: New | G11: 9 | H11: 0 | I11: 0 | J11: 0 | K11: 0 | L11: 0 | M11: 9 | N11: 0 | O11: USD | P11: 0 | Q11: 0 | R11: 0 | S11: 0 | T11: Low traffic | U11: 26.99 | V11: 0 | W11: 21.59 | X11: 0 | Y11: Lower price | AA11: 0 | AB11: 0 | AC11: 0 | AD11: 323.05 | AE11: 0 | AF11: 0.112375 | AG11: cubic feet | AH11: Standard | AI11: 1.011375 | AJ11: US | AK11: gl_toy | AL11: 238733 | AM11: 366 | AN11: 9 | AQ11: 21.59 | AR11: 0 | AS11: 0 | AT11: 0 | AU11: 0 | AV11: 0 | AW11: 0 | AX11: 0 | AY11: 0 | AZ11: 0 | BA11: 7.64 | BB11: 0 | BC11: 0 | BD11: 0 | BE11: 0 | BG11: 0 | BH11: 0 | BI11: 0 | BJ11: 0 | BK11: 0 | BL11: 0 | BM11: 0 | BN11: 0 | BO11: 0 | BP11: 0 | BQ11: 0 | BR11: 0 | BS11: 0 | BT11: 0 | BU11: 9 | BV11: 6.99 | BW11: 0 | BX11: 0 | BZ11: 1 | CA11: Excess | CI11: 46185 | CJ11: 9 | CK11: 0 | CL11: 0 | CM11: 0 | CN11: 0 | CO11: 366 | CP11: unassigned | CQ11: N
A12: 46188 | B12: X003HYQYM5 | C12: B0BLHYTV6G | D12: SoftBuildingBlock-114 | E12: Soft Building Block Sets for Kids Aged 36 Months to 6 Years Old Top STEM Building Blocks for Preschool Large Construction Block Toys for Toddler to Improve Imagination Creativity Hands-on Ability | G12: 0 | H12: -1 | O12: USD | U12: 0 | V12: 0 | W12: 0 | X12: 0 | Y12: NoRestockExcessActionRequired | AB12: 0 | AC12: 0 | AE12: -1 | AJ12: US | AK12: gl_toy | AN12: 0 | AY12: 0 | BB12: 0 | BG12: 0 | BH12: 0 | CJ12: 0 | CK12: 0 | CL12: 0 | CM12: 0 | CN12: 0 | CP12: unassigned | CQ12: N
A13: 46188 | B13: X0050OVSSP | C13: B0CGCM7TXL | D13: 50US-PangXieBubbleMachine | E13: Crab Bubble Bath Maker for The Bathtub,Blows Bubbles and Plays 12 Children’s Songs,Sing-Along Bath Bubble Machine Baby, Toddler Kids Toys Makes Great Gifts for 3 Years Girl Boy | G13: 0 | H13: -1 | O13: USD | U13: 0 | V13: 0 | W13: 0 | X13: 0 | Y13: NoRestockExcessActionRequired | AB13: 0 | AC13: 0 | AE13: -1 | AH13: Standard | AJ13: US | AK13: gl_toy | AM13: 0 | AN13: 0 | AQ13: 13.8 | AY13: 0 | BB13: 0 | BG13: 0 | BH13: 0 | CJ13: 0 | CK13: 0 | CL13: 0 | CM13: 0 | CN13: 0 | CO13: 0 | CP13: unassigned | CQ13: N
A14: 46188 | B14: X003RGLZ45 | C14: B0BYVGS56Z | D14: YaoKongQi Teether11 | E14: ROHSCE Silicone Baby Teether Toys, Cell Phone Teething Toys for Babies 6-12 Months Soft Molar Teether Infant Baby Chew Toys Sensory Remote Teether BPA-Free Gifts, Black+Green | G14: 0 | H14: -1 | O14: USD | U14: 0 | V14: 0 | W14: 0 | X14: 0 | Y14: NoRestockExcessActionRequired | AB14: 0 | AC14: 0 | AE14: -1 | AH14: Standard | AJ14: US | AK14: gl_baby_product | AM14: 0 | AN14: 0 | AQ14: 5.99 | AY14: 0 | BB14: 0 | BC14: 0 | BD14: 0 | BE14: 0 | BG14: 0 | BH14: 0 | CJ14: 0 | CK14: 0 | CL14: 0 | CM14: 0 | CN14: 0 | CO14: 0 | CP14: unassigned | CQ14: N
A15: 46188 | B15: X004YXYQ5F | C15: B0CT5SFK7T | D15: 50US-LiHeRuanCiBall6 | E15: ROHSCE Baby Sensory Balls, 6PCS Soft Textured Spiky Bath Toys 6M+ | F15: New | G15: 23 | H15: 0 | I15: 0 | J15: 23 | K15: 0 | L15: 0 | M15: 0 | N15: 0 | O15: USD | P15: 0 | Q15: 0 | R15: 0 | S15: 1 | T15: Low conversion | U15: 40.99 | V15: 0 | W15: 31.99 | X15: 0 | Y15: Lower price | AB15: 0 | AC15: 0 | AE15: 0.32 | AF15: 0.266389 | AG15: cubic feet | AH15: Standard | AI15: 6.126947 | AJ15: US | AK15: gl_toy | AL15: 2409 | AM15: 87 | AN15: 0 | AP15: 299 | AQ15: 31.99 | AR15: 0 | AS15: 0 | AT15: 0 | AU15: 40.99 | AV15: 0 | AW15: 0 | AX15: 0 | AY15: 0 | AZ15: 0 | BB15: 0 | BC15: 0 | BD15: 0 | BE15: 0 | BG15: 0 | BH15: 0 | BZ15: 1 | CA15: Healthy | CH15: 2080 | CI15: 46186 | CJ15: 23 | CK15: 0 | CL15: 0 | CM15: 0 | CN15: 0 | CO15: 87 | CP15: unassigned | CQ15: N
A16: 46188 | B16: X0046NX0JB | C16: B0BLHZLLK6 | D16: 50-ruantijimu-LK6 | E16: ROHSCE Soft Building Blocks for Toddler, Blocks for Kids 6 Months and up, Large Creative Stacking Blocks 20 PCS STEM Toddler Toys Gifts, Educational Baby Blocks Colorful Soft Block Sets | G16: 0 | H16: -1 | O16: USD | U16: 0 | V16: 0 | W16: 0 | X16: 0 | Y16: NoRestockExcessActionRequired | AB16: 0 | AC16: 0 | AE16: -1 | AJ16: US | AK16: gl_toy | AL16: 26497 | AM16: 0 | AN16: 0 | AQ16: 19.99 | AY16: 0 | BB16: 0 | BG16: 0 | BH16: 0 | CJ16: 0 | CK16: 0 | CL16: 0 | CM16: 0 | CN16: 0 | CO16: 0 | CQ16: N
A17: 46188 | B17: X002LYPVNF | C17: B08FDP4WNK | D17: GameGuaTanZsUs-5001 | E17: Flying Banana Gamer Play & Win Purple Gamepad Tapestry, Cool Colorful Gaming Wall Hanging Tapestry For Men,Bedroom Aesthetic,College Dorm Room Decor(78.7 x 59in) | G17: 0 | H17: -1 | O17: USD | U17: 0 | V17: 0 | W17: 0 | X17: 0 | Y17: NoRestockExcessActionRequired | AB17: 0 | AC17: 0 | AE17: -1 | AH17: Standard | AJ17: US | AK17: gl_home | AM17: 0 | AN17: 0 | AQ17: 18.85 | AY17: 0 | BB17: 0 | BC17: 0 | BD17: 0 | BE17: 0 | BG17: 0 | BH17: 0 | CJ17: 0 | CK17: 0 | CL17: 0 | CM17: 0 | CN17: 0 | CO17: 0 | CP17: unassigned | CQ17: N
A18: 46188 | B18: X0051RPOUT | C18: B0GJXPV9Q1 | D18: 50US-TankYaoKongQi-002 | E18: ROHSCE RC Tank Accessories Controller Set, Replacement 2.4GHz Remote Transmitter and Gesture Sensing Watch Control for Compatible Battle Vehicle Toy Spare Parts | G18: 0 | H18: 0 | I18: 19 | J18: 0 | K18: 0 | L18: 0 | M18: 0 | N18: 0 | O18: USD | U18: 0 | V18: 0 | W18: 0 | X18: 0 | Y18: NoRestockExcessActionRequired | AB18: 0 | AC18: 0 | AE18: 0 | AF18: 0.038098 | AG18: cubic feet | AH18: Standard | AI18: 0 | AJ18: US | AK18: gl_toy | AM18: 0 | AN18: 0 | AQ18: 22.99 | AV18: 0 | AW18: 19 | AX18: 0 | AY18: 0 | AZ18: 0 | BB18: 0 | BC18: 0 | BD18: 0 | BE18: 0 | BG18: 19 | BH18: 0 | CI18: 46186 | CJ18: 0 | CK18: 0 | CL18: 0 | CM18: 0 | CN18: 19 | CO18: 85 | CP18: unassigned | CQ18: N
A19: 46188 | B19: X004ETS49X | C19: B0CRDL2HD6 | D19: 50-PinkGuiDaoClaw-HD6 | E19: ROHSCE Claw Machine for Kids, Mini Vending Machine Toys for Girls, Arcade Game Toy for Ages 8-13, Electronic Claw Game Machine for Party with Lights Sound, Birthday Gifts for Ages 4+ | G19: 0 | H19: -1 | O19: USD | P19: 0 | Q19: 0 | R19: 0 | S19: 0 | U19: 0 | V19: 0 | W19: 0 | X19: 0 | Y19: NoRestockExcessActionRequired | AB19: 0 | AC19: 0 | AE19: -1 | AH19: Oversize | AJ19: US | AK19: gl_toy | AL19: 192027 | AN19: 0 | AQ19: 79.99 | AR19: 0 | AS19: 0 | AT19: 0 | AU19: 0 | AY19: 0 | BB19: 0 | BC19: 0 | BD19: 0 | BE19: 0 | BG19: 0 | BH19: 0 | CJ19: 0 | CK19: 0 | CL19: 0 | CM19: 0 | CN19: 0 | CP19: unassigned | CQ19: N
A20: 46188 | B20: X004QU0Y93 | C20: B0DTTVCDCG | D20: 50US-GenSuiYa-001 | E20: ROHSCE Duck Tummy Time Toys for Baby, Musical Toys for Toddlers, Baby Crawling Baby Toys for Boys Girls, Early Learning Education, Christmas Birthday Gifts for Babies 18 Months | G20: 0 | H20: -1 | O20: USD | P20: 0 | Q20: 0 | R20: 0 | S20: 0 | U20: 0 | V20: 0 | W20: 0 | X20: 0 | Y20: NoRestockExcessActionRequired | AB20: 0 | AC20: 0 | AE20: -1 | AH20: Standard | AJ20: US | AK20: gl_toy | AM20: 0 | AN20: 0 | AQ20: 22.49 | AR20: 0 | AS20: 0 | AT20: 0 | AU20: 0 | AY20: 0 | BB20: 0 | BC20: 0 | BD20: 0 | BE20: 0 | BG20: 0 | BH20: 0 | BZ20: 1 | CA20: Out of stock | CJ20: 0 | CK20: 0 | CL20: 0 | CM20: 0 | CN20: 0 | CO20: 0 | CP20: unassigned | CQ20: N
A21: 46188 | B21: X0051RXUQ9 | C21: B0GJYDMJ8D | D21: 50US-TankTiHuanJiShen-03 | E21: ROHSCE Green RC Tank Accessories Replacement Body Shell, Plastic Hull Cover for Remote Control Tank Model, Repair Spare Part Upgrade Kit for RC Hobby Tracked Vehicle | F21: New | G21: 20 | H21: 0 | I21: 20 | J21: 0 | K21: 0 | L21: 0 | M21: 0 | N21: 0 | O21: USD | T21: Low conversion | U21: 41.99 | V21: 0 | W21: 29.99 | X21: 0 | Y21: Lower price | AA21: 0 | AB21: 0 | AC21: 0 | AD21: 0 | AE21: 0 | AF21: 0.091635 | AG21: cubic feet | AH21: Standard | AI21: 1.8327 | AJ21: US | AK21: gl_toy | AL21: 206385 | AM21: 28 | AN21: 0 | AQ21: 29.99 | AV21: 0 | AW21: 20 | AX21: 0 | AY21: 0 | AZ21: 0 | BA21: 1.31 | BB21: 0 | BC21: 0 | BD21: 0 | BE21: 0 | BG21: 0 | BH21: 0 | CI21: 46186 | CJ21: 20 | CK21: 0 | CL21: 0 | CM21: 0 | CN21: 0 | CO21: 28 | CP21: unassigned | CQ21: N
A22: 46188 | B22: B08F3GFQYJ | C22: B08F3GFQYJ | D22: JIaJieMao12taozhuang-0012 | E22: Yayalovehomee Magnetic Eyelashes and Magnetic Eyeliner Kit, 12 Pairs of Different Styles Reusable Magnetic Eyelashes with 2 Special Magnetic Eyeliners and Tweezers, Easy to Apply with Natural Look | G22: 0 | H22: -1 | O22: USD | U22: 0 | V22: 0 | W22: 0 | X22: 0 | Y22: NoRestockExcessActionRequired | AB22: 0 | AC22: 0 | AE22: -1 | AJ22: US | AK22: gl_beauty | AN22: 0 | AY22: 0 | BB22: 0 | BG22: 0 | BH22: 0 | CJ22: 0 | CK22: 0 | CL22: 0 | CM22: 0 | CN22: 0 | CP22: unassigned | CQ22: N
A23: 46188 | B23: X003F87X73 | C23: B0BHF5ZBS6 | D23: TuMaMaBalls | E23: ROHSCE Montessori Sensory Balls for Babies 6 to 12 Months, Soft Textured Multi Sensory Toys, BPA Free - Gift Set Includes: Toddler Ball, Bath Toys | G23: 0 | H23: -1 | O23: USD | U23: 0 | V23: 0 | W23: 0 | X23: 0 | Y23: NoRestockExcessActionRequired | AB23: 0 | AC23: 0 | AE23: -1 | AH23: Standard | AJ23: US | AK23: gl_toy | AM23: 0 | AN23: 0 | AQ23: 15.99 | AY23: 0 | BB23: 0 | BC23: 0 | BD23: 0 | BE23: 0 | BG23: 0 | BH23: 0 | CJ23: 0 | CK23: 0 | CL23: 0 | CM23: 0 | CN23: 0 | CO23: 0 | CP23: unassigned | CQ23: N
A24: 46188 | B24: B09GVMZLSF | C24: B09GVMZLSF | D24: JIMU9JIAN | E24: Flying Banana Building Blocks Baby Toys for 3 Months and up, Soft Squeeze Sensory Colorful Teething Chewing Educational Stacking Blocks with 3D Embossed Patterns | G24: 0 | H24: -1 | O24: USD | U24: 0 | V24: 0 | W24: 0 | X24: 0 | Y24: NoRestockExcessActionRequired | AB24: 0 | AC24: 0 | AE24: -1 | AH24: Standard | AJ24: US | AK24: gl_toy | AM24: 0 | AN24: 0 | AQ24: 9.99 | AY24: 0 | BB24: 0 | BC24: 0 | BD24: 0 | BE24: 0 | BG24: 0 | BH24: 0 | CJ24: 0 | CK24: 0 | CL24: 0 | CM24: 0 | CN24: 0 | CO24: 0 | CP24: unassigned | CQ24: N
A25: 46188 | B25: X003EOK7TJ | C25: B0BGBWZY8G | D25: BubbleGun-Blue-2 | E25: Automatic Bubble Machine for Kids, Kids Bubble Makers Bubble Machine Gun with Light, Automatic Gatling Bubble Gun for Adult & Kids, Rechargeable Bubble Machine for Party, Large Bubble Blower | G25: 0 | H25: -1 | O25: USD | U25: 0 | V25: 0 | W25: 0 | X25: 0 | Y25: NoRestockExcessActionRequired | AB25: 0 | AC25: 0 | AE25: -1 | AH25: Standard | AJ25: US | AK25: gl_toy | AM25: 0 | AN25: 0 | AQ25: 29.99 | AY25: 0 | BB25: 0 | BC25: 0 | BD25: 0 | BE25: 0 | BG25: 0 | BH25: 0 | CJ25: 0 | CK25: 0 | CL25: 0 | CM25: 0 | CN25: 0 | CO25: 0 | CP25: unassigned | CQ25: N
A26: 46188 | B26: X00554YAPD | C26: B0GXNYXWXP | D26: 50US-yinyueguPINK-003 | E26: ROHSCE Infant Musical Drum Toy – Colorful Interactive Drum Playset with Lights and Sounds, Perfect for Enhancing Sensory Awareness, Motor Skills, and Early Cognitive Development | F26: New | G26: 0 | H26: -1 | O26: USD | U26: 55.99 | V26: 0 | W26: 0 | X26: 0 | Y26: Edit listing | AB26: 0 | AC26: 0 | AE26: -1 | AH26: Standard | AJ26: US | AK26: gl_toy | AN26: 0 | AY26: 0 | BB26: 20 | BC26: 20 | BD26: 0 | BE26: 0 | BG26: 0 | BH26: 0 | CJ26: 20 | CK26: 0 | CL26: 0 | CM26: 0 | CN26: 0 | CP26: unassigned | CQ26: N
A27: 46188 | B27: X004YIAEBZ | C27: B0DSZRWS75 | D27: 50US-TankRuanDanLanTou | E27: ROHSCE Blue Foam Dart Launcher Attachment for RC Toy Vehicle, Soft Foam Dart Shooter Replacement Module for Remote Control Stunt Car Toy, Kids RC Toy Accessory Spare Part | F27: New | G27: 20 | H27: 0 | I27: 0 | J27: 20 | K27: 0 | L27: 0 | M27: 0 | N27: 0 | O27: USD | T27: Low conversion | U27: 28.49 | V27: 0 | W27: 22.79 | X27: 0 | Y27: Lower price | AA27: 0 | AB27: 0 | AC27: 0 | AD27: 67.83 | AE27: 0 | AF27: 0.15428 | AG27: cubic feet | AH27: Standard | AI27: 3.0856 | AJ27: US | AK27: gl_toy | AL27: 206385 | AN27: 6 | AQ27: 22.79 | AV27: 0 | AW27: 0 | AX27: 0 | AY27: 0 | AZ27: 0 | BA27: 2.21 | BB27: 0 | BC27: 0 | BD27: 0 | BE27: 0 | BG27: 0 | BH27: 0 | CA27: Excess | CI27: 46186 | CJ27: 20 | CK27: 0 | CL27: 0 | CM27: 0 | CN27: 0 | CP27: unassigned | CQ27: N
A28: 46188 | B28: X004SQ5VN9 | C28: B0FGC9SZ4D | D28: HuocheMaoRongChe002 | E28: ROHSCE Plush Remote Control Train for Toddlers, Soft RC Car with 2.4GHz Two-Button Remote, Washable Soft Cover, for Boys & Girls Ages 18 Months+ | G28: 0 | H28: -1 | O28: USD | P28: 0 | Q28: 0 | R28: 0 | S28: 0 | U28: 0 | V28: 0 | W28: 0 | X28: 0 | Y28: NoRestockExcessActionRequired | AB28: 0 | AC28: 0 | AE28: -1 | AH28: Standard | AJ28: US | AK28: gl_toy | AM28: 0 | AN28: 0 | AQ28: 35.99 | AR28: 0 | AS28: 0 | AT28: 0 | AU28: 0 | AY28: 0 | BB28: 0 | BC28: 0 | BD28: 0 | BE28: 0 | BG28: 0 | BH28: 1 | BZ28: 1 | CA28: Out of stock | CJ28: 0 | CK28: 0 | CL28: 0 | CM28: 0 | CN28: 0 | CO28: 0 | CP28: unassigned | CQ28: N
A29: 46188 | B29: X003DY3UUN | C29: B0BDFBXDHP | D29: SZQchuxuGuan-03 | E29: ROHSCE Sensory Balls Montessori Toys for Babies 6-12 Months, Baby Sensory Toys Turtle Toys Bright Color Textured Multi Soft Balls, BPA Free Ball for Toddlers 1-3 Teething Gifts | G29: 49 | H29: -1 | O29: USD | P29: 0 | Q29: 10 | R29: 19 | S29: 43 | W29: -1 | X29: -1 | Y29: CreateShippingPlan | AA29: 0 | AB29: 0 | AC29: 0 | AD29: 0 | AE29: -1 | AH29: Standard | AJ29: US | AK29: gl_sports | AL29: 9437 | AM29: 65 | AN29: 0 | AO29: 19 | AP29: 14 | AQ29: 29.99 | AR29: 0 | AS29: 249.9 | AT29: 462.42 | AU29: 1046.18 | AY29: 0 | BA29: 6.17 | BB29: 0 | BC29: 0 | BD29: 0 | BE29: 0 | BG29: 0 | BH29: 1 | BY29: 126.4 | BZ29: 48 | CA29: Healthy | CB29: 54 | CC29: 46195 | CD29: 46188 | CE29: Yes | CF29: No | CG29: 126.4 | CH29: 77.7 | CJ29: 50 | CK29: 1 | CL29: 0 | CM29: 0 | CN29: 0 | CO29: 65 | CP29: unassigned | CQ29: N
A30: 46188 | B30: X004957WDB | C30: B0CJ5B2DXY | D30: 50busyboard-0001 | E30: ROHSCE Montessori Busy Board Sensory Toys for Toddlers 1-3, Activity Music & LED Light Up Montessori Toys for 2+ Year Old, Travel Toys for 2 Year Old Boys & Girls, 2025 | F30: New | G30: 39 | H30: 0 | I30: 11 | J30: 40 | K30: 0 | L30: 0 | M30: 0 | N30: 0 | O30: USD | P30: 4 | Q30: 9 | R30: 22 | S30: 32 | U30: 39.99 | V30: 0 | W30: 39.99 | X30: 0 | Y30: NoExcessInventory | AA30: 0 | AB30: 0 | AC30: 0 | AD30: 0 | AE30: 0.49 | AF30: 0.300229 | AG30: cubic feet | AH30: Standard | AI30: 11.708931 | AJ30: US | AK30: gl_toy | AL30: 203254 | AM30: 64 | AN30: 0 | AO30: 17 | AP30: 15 | AQ30: 29.99 | AR30: 131.06 | AS30: 299.51 | AT30: 729.18 | AU30: 1122.78 | AV30: 11 | AW30: 0 | AX30: 0 | AY30: 0 | AZ30: 0 | BA30: 9.49 | BB30: 0 | BC30: 0 | BD30: 0 | BE30: 0 | BG30: 8 | BH30: 4 | BY30: 159.9 | BZ30: 39 | CA30: Healthy | CB30: 13 | CC30: 46194 | CD30: 46188 | CE30: Yes | CF30: No | CG30: 144.8 | CH30: 159.9 | CI30: 46186 | CJ30: 43 | CK30: 4 | CL30: 0 | CM30: 0 | CN30: 8 | CO30: 77 | CP30: unassigned | CQ30: N
A31: 46188 | B31: X004JMVLFJ | C31: B0GG4GS8FZ | D31: 50-WuziMangLuBan | E31: ROHSCE Baby Busy Board for 1 Year Old, Musical Montessori House Busy Board with Light & Music, Toddler Activity Toy for Boys Girls 12-18 Months, 1 Year Old Birthday Gift | F31: New | G31: 5 | H31: -1 | O31: USD | P31: 1 | Q31: 10 | R31: 16 | S31: 30 | U31: 27.99 | V31: 0 | W31: 0 | X31: 0 | Y31: CreateShippingPlan | AB31: 0 | AC31: 0 | AE31: -1 | AH31: Standard | AJ31: US | AK31: gl_toy | AL31: 203254 | AM31: 18 | AN31: 0 | AO31: 2 | AP31: 2 | AQ31: 27.99 | AR31: 27.99 | AS31: 279.9 | AT31: 447.84 | AU31: 831.7 | AY31: 0 | BB31: 0 | BC31: 0 | BD31: 0 | BE31: 0 | BG31: 1 | BH31: 0 | BY31: 20.7 | BZ31: 24 | CA31: Low stock | CB31: 42 | CC31: 46187 | CD31: 46188 | CE31: Yes | CF31: No | CG31: 12.6 | CH31: 20.7 | CJ31: 9 | CK31: 4 | CL31: 0 | CM31: 1 | CN31: 0 | CO31: 20 | CP31: unassigned | CQ31: N
A32: 46188 | B32: X003EOGQWL | C32: B0BGBXHL7T | D32: BubbleGun-Blue-1 | E32: ROHSCE Automatic Bubble Machine for Kids, Kids Bubble Makers Bubble Machine Gun with Light, Automatic Gatling Bubble Gun for Kids, Rechargeable Bubble Machine Bubble Blower for Party, Blue | G32: 0 | H32: -1 | O32: USD | U32: 0 | V32: 0 | W32: 0 | X32: 0 | Y32: NoRestockExcessActionRequired | AB32: 0 | AC32: 0 | AE32: -1 | AH32: Standard | AJ32: US | AK32: gl_toy | AN32: 0 | AQ32: 63.99 | AY32: 0 | BB32: 0 | BC32: 0 | BD32: 0 | BE32: 0 | BG32: 0 | BH32: 0 | CJ32: 0 | CK32: 0 | CL32: 0 | CM32: 0 | CN32: 0 | CP32: unassigned | CQ32: N
A33: 46188 | B33: X003RGBQ1R | C33: B0BYVFS9H1 | D33: YaoKongQi Teether06 | E33: ROHSCE Silicone Baby Teether Toys, Mobile Phone Shape Teething Toys for Babies 6-12 Months Soft Molar Teether Infant Baby Chew Toys Sensory Phone Teether for Baby BPA-Free Gifts, Yellow | G33: 0 | H33: -1 | O33: USD | U33: 0 | V33: 0 | W33: 0 | X33: 0 | Y33: NoRestockExcessActionRequired | AB33: 0 | AC33: 0 | AE33: -1 | AH33: Standard | AJ33: US | AK33: gl_baby_product | AM33: 0 | AN33: 0 | AQ33: 3.49 | AY33: 0 | BB33: 0 | BC33: 0 | BD33: 0 | BE33: 0 | BG33: 0 | BH33: 0 | CJ33: 0 | CK33: 0 | CL33: 0 | CM33: 0 | CN33: 0 | CO33: 0 | CP33: unassigned | CQ33: N
A34: 46188 | B34: X003E7KZCZ | C34: B0BFDXJ925 | D34: shouchifengrenji | E34: Mini Handheld Electric Sewing Machine for Kids & Sewing Beginners, Portable Sewing Machine with Sewing Kit for Household Sewing | G34: 0 | H34: -1 | O34: USD | U34: 0 | V34: 0 | W34: 0 | X34: 0 | Y34: NoRestockExcessActionRequired | AB34: 0 | AC34: 0 | AE34: -1 | AJ34: US | AK34: gl_home | AN34: 0 | AY34: 0 | BB34: 0 | BG34: 0 | BH34: 0 | CJ34: 0 | CK34: 0 | CL34: 0 | CM34: 0 | CN34: 0 | CP34: unassigned | CQ34: N
A35: 46188 | B35: X00335CKC1 | C35: B09MK2ZTK1 | D35: 50-FB-bluepuzzle-001 | E35: Flying Banana Wooden Face Changing Cube Matching Game Puzzle, Expressions Matching Block Puzzles Building Cubes Game Educational Social Toys for Kids Ages 3 Years and Up | G35: 0 | H35: -1 | O35: USD | U35: 0 | V35: 0 | W35: 0 | X35: 0 | Y35: NoRestockExcessActionRequired | AB35: 0 | AC35: 0 | AE35: -1 | AJ35: US | AK35: gl_toy | AN35: 0 | AY35: 0 | BB35: 0 | BG35: 0 | BH35: 0 | CJ35: 0 | CK35: 0 | CL35: 0 | CM35: 0 | CN35: 0 | CP35: unassigned | CQ35: N
A36: 46188 | B36: X003WOREFL | C36: B0BLKBV7T2 | D36: YaokongYueyeche-006 | E36: ROHSCE RC Tank that Shoots Gesture Sensing RC Tank, 2.4GHz Battle Soft Bullets Hand Control Car Drift Remote Control Trucks for Boys & Girls 8-12, Remote Control Tank with Light Music | G36: 0 | H36: -1 | O36: USD | U36: 0 | V36: 0 | W36: 0 | X36: 0 | Y36: NoRestockExcessActionRequired | AB36: 0 | AC36: 0 | AE36: -1 | AJ36: US | AK36: gl_toy | AL36: 206385 | AM36: 0 | AN36: 0 | AQ36: 69.99 | AY36: 0 | BB36: 0 | BG36: 0 | BH36: 0 | CB36: 56 | CC36: 46187 | CJ36: 0 | CK36: 0 | CL36: 0 | CM36: 0 | CN36: 0 | CO36: 0 | CP36: unassigned | CQ36: N
A37: 46188 | B37: X004MPM67P | C37: B0C7G9L4GD | D37: 50US-MaoCiBabyBall002 | E37: ROHSCE Baby Sensory Balls 6–12 Months, Soft Spiky Textured Teething Toys for Infants Montessori Grasping & Learning Balls for Tactile Development & Play | F37: New | G37: 12 | H37: 0 | I37: 1 | J37: 11 | K37: 0 | L37: 0 | M37: 0 | N37: 0 | O37: USD | P37: 2 | Q37: 6 | R37: 9 | S37: 13 | T37: Low traffic | U37: 18.99 | V37: 15.99 | W37: 15.99 | X37: 0 | Y37: Create Outlet deal | AA37: 11.19 | AB37: 2 | AC37: 0 | AD37: 238.72 | AE37: 0.74 | AF37: 0.0649 | AG37: cubic feet | AH37: Standard | AI37: 0.7788 | AJ37: US | AK37: gl_sports | AL37: 329212 | AM37: 114 | AN37: 12 | AO37: 14 | AP37: 22 | AQ37: 15.99 | AR37: 31.98 | AS37: 95.94 | AT37: 149.91 | AU37: 225.87 | AV37: 0 | AW37: 0 | AX37: 1 | AY37: 0 | AZ37: 0 | BA37: 0.56 | BB37: 10 | BC37: 10 | BD37: 0 | BE37: 0 | BG37: 0 | BH37: 0 | BY37: 120.9 | BZ37: 7 | CA37: Excess | CD37: 46188 | CE37: Yes | CF37: No | CG37: 63.3 | CH37: 120.9 | CI37: 46186 | CJ37: 22 | CK37: 0 | CL37: 0 | CM37: 0 | CN37: 0 | CO37: 192 | CP37: unassigned | CQ37: N
A38: 46188 | B38: X004SHE0FN | C38: B08FM4LMWR | D38: 50US-NEWp-Sewing Machine White020 | E38: Mini Sewing Machine for Beginners-Maquina de Coser, Easy Automatic Sewing Machine with Extension Table, Household Electric Portable Sewing Tool with Sewing Kit, Small, for All Age, Kids or Adults | G38: 0 | H38: -1 | O38: USD | P38: 0 | Q38: 0 | R38: 0 | S38: 0 | U38: 0 | V38: 0 | W38: 0 | X38: 0 | Y38: NoRestockExcessActionRequired | AB38: 0 | AC38: 0 | AE38: -1 | AH38: Standard | AJ38: US | AK38: gl_home | AL38: 32209 | AM38: 0 | AN38: 0 | AQ38: 34.99 | AR38: 0 | AS38: 0 | AT38: 0 | AU38: 0 | AY38: 0 | BB38: 0 | BC38: 0 | BD38: 0 | BE38: 0 | BG38: 0 | BH38: 0 | BZ38: 1 | CA38: Out of stock | CB38: 231 | CC38: 46188 | CJ38: 0 | CK38: 0 | CL38: 0 | CM38: 0 | CN38: 0 | CO38: 0 | CP38: unassigned | CQ38: N
A39: 46188 | B39: X003RGBNZL | C39: B0BYVFTT4X | D39: YaoKongQi Teether09 | E39: ROHSCE Silicone Baby Teether Toys, Remote Game Control Teething Toys for Babies 6-12 Months Soft Molar Teether Infant Baby Chew Toys Sensory Remote Teether BPA-Free Gifts, Black+Dark Blue | G39: 0 | H39: -1 | O39: USD | U39: 0 | V39: 0 | W39: 0 | X39: 0 | Y39: NoRestockExcessActionRequired | AB39: 0 | AC39: 0 | AE39: -1 | AH39: Standard | AJ39: US | AK39: gl_baby_product | AM39: 0 | AN39: 0 | AQ39: 3.99 | AY39: 0 | BB39: 0 | BC39: 0 | BD39: 0 | BE39: 0 | BG39: 0 | BH39: 0 | CJ39: 0 | CK39: 0 | CL39: 0 | CM39: 0 | CN39: 0 | CO39: 0 | CP39: unassigned | CQ39: N
A40: 46188 | B40: X003G49PO5 | C40: B09GVMZLSF | D40: SoftBuildingBlock-9 | E40: Flying Banana Building Blocks Baby Toys for 3 Months and up, Soft Squeeze Sensory Colorful Teething Chewing Educational Stacking Blocks with 3D Embossed Patterns | G40: 0 | H40: -1 | O40: USD | U40: 0 | V40: 0 | W40: 0 | X40: 0 | Y40: NoRestockExcessActionRequired | AB40: 0 | AC40: 0 | AE40: -1 | AH40: Standard | AJ40: US | AK40: gl_toy | AM40: 0 | AN40: 0 | AQ40: 9.99 | AY40: 0 | BB40: 0 | BC40: 0 | BD40: 0 | BE40: 0 | BG40: 0 | BH40: 0 | CJ40: 0 | CK40: 0 | CL40: 0 | CM40: 0 | CN40: 0 | CO40: 0 | CP40: unassigned | CQ40: N
...

Sheet Sheet3
B8: 50等级 | G8: 149
B10: B07SRSJZSL | C10: B07SRSJZSL | D10: SS | G10: 149US-PinkNiuDanJi | H10: X004U9OXE7 | I10: B0CRDL2HD6 | J10: S
B11: B07SVYD7RV B07SX1K48R | C11: B07SVYD7RV | D11: SS | G11: 149US-SoftCiLiGuan26P-007 | H11: X004UB6DNT | I11: B0FHPSR92X | J11: A
B12: B08J3MZQ2M | C12: B08J3MZQ2M | D12: SS | G12: ZiMuYouXi-0002 | H12: X004UBDOYZ | I12: B0FMK6V5N6 | J12: A
B13: B0B9N5PX8H | C13: B0B9N5PX8H | D13: SS | G13: 149US-Chibang-devil | H13: X004UT0YYP | I13: B0F23T2MLJ
B14: B0BLHXCYWM B0DPSZLZNL | C14: B0BLHXCYWM | D14: SS
B15: B08FM4LMWR | C15: B08FM4LMWR | D15: SS | G15: 149-KeHuanWanJvQiang-001 | H15: X004TJJJ8X | I15: B0FHPVDGBQ | J15: P
B16: B0BLHZLLK6 B0DPSZLZNL | C16: B0BLHZLLK6 | D16: SS | G16: 149US-22TuZiMaoXianJi-NEW | H16: X004ZG26M1 | I16: B0GGR3FL2X | J16: A
G17: 149-xiaohaohudie-6J7 | H17: X004C26F2F | I17: B0CT8VF6J7 | J17: SS
B18: B0CW9NVMSZ | C18: B0CW9NVMSZ | D18: SS | G18: 149-ChiLunPinTu-GX6 | H18: X004FBT7HD | I18: B0CT5HKGX6 | J18: A
B19: B0CWH2F9MM B0DC3H9K53 | C19: B0CWH2F9MM | D19: SS | G19: 149-shishangnvhai-1GJ | H19: X004EGTBBV | I19: B0DCNWK1GJ | J19: S
B20: B0CJ6NHRQ2 | C20: B0CJ6NHRQ2 | D20: S | G20: 149-niwajiang-0002 | H20: X004EG8HB1 | I20: B0FP52CS55 | J20: S
B21: B0CT5R73WR | C21: B0CT5R73WR | D21: S | G21: 149US-PinkCaiHongWuClaw | H21: X004U9P0AN | I21: B0C5CWSDGX | J21: S
G22: 149US-PinkNiuDanClaw | H22: X004UEQAMP | I22: B0FPC6D218 | J22: S
B23: B0BLKBV7T2 | C23: B0BLKBV7T2 | D23: S
B24: B09W3RZZQV | C24: B09W3RZZQV | D24: A | G24: 149US-XiaoHaoTuZiMaoXianJi | H24: X004ZG6JRJ | I24: B0GGQDW816 | J24: A
B25: B0BDFBXDHP B0BDF8ZFC2 | C25: B0BDFBXDHP | D25: A | G25: 149-Reminxiangji-Pink | H25: X004SQHCWH | I25: B0FHHDCYFL | J25: A
B26: B0838NV866 | C26: B0838NV866 | D26: A | G26: 149HuaRongDaoYellow2 | H26: X004S25IZT | I26: B0F7H2HJ9K | J26: A
B27: B08G4MQP82 B0BW3SH2KR | C27: B08G4MQP82 | D27: SS | G27: HeJinLuoSiJiMu-0002 | H27: X004UBFH8L | I27: B0FK4FYRZJ | J27: A
B28: B0CJ6Q3PV7 | C28: B0CJ6Q3PV7 | D28: A | G28: 149-BlueNiuDanWaWaJi | H28: X004RPX36D | I28: B0CRDNDFLC | J28: SS
B29: B0BDFBYHNQ B0BDF8ZFC2 | C29: B0BDFBYHNQ | D29: A | G29: 149US-HongHeJiMu | H29: X004YTQB0H | I29: B09M8D5Z9S | J29: A
B30: B0CDGK13SD B0DPSZLZNL | C30: B0CDGK13SD | D30: A | G30: 149-YiCheHuaRongDao-1 | H30: X004S1P3E1 | I30: B0F7GZ1D8D | J30: A
B31: B07KD7NDK9 | C31: B07KD7NDK9 | D31: A | G31: ZiMuYouXi-0003 | H31: X004UBLE3D | I31: B0FMK6R2HS | J31: A
B32: B0CJ6P3P9F | C32: B0CJ6P3P9F | D32: A | G32: HeJinLuoSiJiMu-0008 | H32: X004UBFFD3 | I32: B0FK4GKPTM | J32: A
B33: B0BGKRJGPZ B0CRV273M2 | C33: B0BGKRJGPZ | D33: S | G33: 149US-DongWuChiLun | H33: X004MJ8UFN | I33: B0C65SQ3DV | J33: S
B34: B0CDGKTNS9 B0DPSZLZNL | C34: B0CDGKTNS9 | D34: S | G34: 149-qiuqianniwaA10 | H34: X004SJLWUR | I34: B0F1Y548MZ | J34: S
B35: B0CT5TKD1T | C35: B0CT5TKD1T | D35: A | G35: rideontrain 0007 | H35: X004DUX6HN | I35: B0DBZBTLVN | J35: S
... B38: B0CW9GKWSL | C38: B0CW9GKWSL | D38: A | G38: 149-XiShuizhuo-Blue | H38: X004P3IH13 | I38: B0F7FBDB45 | J38: P
B39: B07FR7N4M3 | C39: B07FR7N4M3 | D39: A | G39: 149-Reminxiangji-Blue | H39: X004SQEYNH | I39: B0FHHJXQ5S
