Workbook

Sheet 报关单
A1: 中华人民共和国海关出口货物报关单
A2: 预录入编号： | F2: 申报口岸: | I2: 海关编号:
A3: 境内发货人 | E3: 出境关别 | F3: ( ) | G3: 出口日期 | K3: 申报日期 | O3: 备案号
A4: 深圳市宴君跨境电商有限公司
A5: 境外收货人 | E5: 运输方式 | F5: ( ) | G5: 运输工具名称及航次号 | K5: 提运单号
A6: Amazon.com Services, Inc.
A7: 生产销售单位 | E7: 监管方式 | F7: ( ) | G7: 征免性质 | H7: ( ) | K7: 许可证号
A8: 深圳市宴君跨境电商有限公司 | E8: 9810 | G8: 一般征税
A9: 合同协议号 | E9: 贸易国(地区) | F9: ( ) | G9: 运抵国(地区) | H9: ( ) | K9: 指运港 | L9: ( ) | O9: 离境口岸 | P9: ( )
A10: FBA19GTDMPSV | E10: 美国 | G10: =E10 -> 美国 | K10: =E10 -> 美国
A11: 包装种类 | C11: ( ) | E11: 件数 | F11: 毛重（千克） | G11: 净重（千克） | I11: 成交方式 | J11: ( ) | K11: 运费 | N11: 保费 | Q11: 杂费
A12: 纸箱包装 | E12: 5 | F12: 26.38 | G12: 25.12 | I12: CNF
A13: 随附单证及编号
A15: 标记唛码及备注：
A16: 备注：
L17: 报关联系电话： | T17: 合计：
A18: 特殊关系确认: | D18: 价格影响确认： | F18: 支付特许权使用费: | I18: 自报自缴: | K18: 出口不填 | L18: 原产国/目的国/货源地未注明的项默认与提供的项相同 | T18: =SUM(T20:T489) -> 0 | U18: =SUM(U20:U489) -> 0 | V18: =SUM(V20:V489) -> 0
A19: 项号 | B19: 商品编号 | D19: 商品名称及规格型号 | G19: 数量及单位 | I19: 单价/总价/币制 | K19: 原产国（地区） | M19: 最终目的国（地区） | P19: 境内货源地 | S19: 征免 | T19: 净重 | U19: 毛重 | V19: 件数
A20: 1 | B20: 9503008900 | D20: 手抓球 | G20: 67 | H20: 个 | I20: 2 | K20: 中国 | M20: 美国 | P20: 广东汕头 | S20: 照章征税
D21: 给孩子玩具for baby development | G21: 67 | H21: 盒 | I21: 134
G22: 4 | H22: 箱 | I22: 美元 | K22: 件数 | L22: 4 | M22: 净重 (KG): | P22: 毛重 (KG):
A23: 2 | B23: 9503008900 | D23: 软积木 | G23: 56 | H23: 个 | I23: 3 | K23: 中国 | M23: 美国 | P23: 广东汕头 | S23: 照章征税
D24: 给孩子玩具for baby development | G24: 56 | H24: 盒 | I24: 168
G25: 4 | H25: 箱 | I25: 美元 | K25: 件数 | L25: 4 | M25: 净重 (KG): | P25: 毛重 (KG):
A26: 3 | B26: 9503008900 | D26: 球铃组合 | G26: 7 | H26: 个 | I26: 3 | K26: 中国 | M26: 美国 | P26: 广东汕头 | S26: 照章征税
D27: 给孩子玩具for baby development | G27: 7 | H27: 盒 | I27: 21
G28: 1 | H28: 箱 | I28: 美元 | K28: 件数 | L28: 1 | M28: 净重 (KG): | P28: 毛重 (KG):
A29: 4 | B29: 9503008900 | D29: 落球塔 | G29: 2 | H29: 个 | I29: 6 | K29: 中国 | M29: 美国 | P29: 广东汕头 | S29: 照章征税
D30: 给孩子玩具for baby development | G30: 2 | H30: 盒 | I30: 12
G31: 1 | H31: 箱 | I31: 美元 | K31: 件数 | L31: 1 | M31: 净重 (KG): | P31: 毛重 (KG):
A32: 5 | B32: 8452101000 | D32: 缝纫机 | G32: 2 | H32: 个 | I32: 6 | K32: 中国 | M32: 美国 | P32: 广东汕头 | S32: 照章征税
D33: 培养缝纫技能Cultivate sewing skills | G33: 2 | H33: 盒 | I33: 12
G34: 1 | H34: 箱 | I34: 美元 | K34: 件数 | L34: 1 | M34: 净重 (KG): | P34: 毛重 (KG):
A35: 6 | B35: 3926400000 | D35: 假泥鳅 | G35: 8 | H35: 个 | I35: 2 | K35: 中国 | M35: 美国 | P35: 广东汕头 | S35: 照章征税
D36: for fishing钓鱼 | G36: 8 | H36: 盒 | I36: 16
G37: 1 | H37: 箱 | I37: 美元 | K37: 件数 | L37: 1 | M37: 净重 (KG): | O37: 25.12 | P37: 毛重 (KG): | R37: 26.38
A38: 7 | B38: 9503008900 | D38: 立体拼图 | G38: 8 | H38: 个 | I38: 2 | K38: 中国 | M38: 美国 | P38: 广东汕头 | S38: 照章征税
D39: 给孩子玩具for baby development | G39: 8 | H39: 盒 | I39: 16
G40: 1 | H40: 箱 | I40: 美元 | K40: 件数 | L40: 1 | M40: 净重 (KG): | P40: 毛重 (KG):
A41: 8 | B41: 9503008900 | D41: 升空火箭 | G41: 6 | H41: 个 | I41: 9 | K41: 中国 | M41: 美国 | P41: 广东汕头 | S41: 照章征税
...

Sheet 发票
A1: 發票 INVOICE
F2: 發票編號 Invoice NO: | G2: =报关单!A10 -> FBA19GTDMPSV
A3: 商 號 Sold to Massrs: | C3: =报关单!A6 -> Amazon.com Services, Inc. | F3: 日 期 DATE: | G3: 46006
F6: 成交方式： | G6: =报关单!V4 -> 0
A7: 標記號碼 Mark & No | C7: 貨物名稱 Description | D7: 數量 Quantity | F7: 單價 Unit price | G7: 總金額 Amount
B8: 1 | C8: =OFFSET(报关单!$D$1,ROW(报关单!D1)*3+16,0) -> 手抓球 | D8: =报关单!G21 -> 67 | E8: =报关单!H21 -> 盒 | F8: =报关单!I20 -> 2 | G8: =OFFSET(报关单!$I$1,ROW(报关单!I1)*3+18,0) -> 美元 | H8: =OFFSET(报关单!$I$1,ROW(报关单!I1)*3+17,0) -> 134
B9: 2 | C9: =OFFSET(报关单!$D$1,ROW(报关单!D2)*3+16,0) -> 软积木 | D9: =报关单!G24 -> 56 | E9: =报关单!H24 -> 盒 | F9: =报关单!I23 -> 3 | G9: =OFFSET(报关单!$I$1,ROW(报关单!I2)*3+18,0) -> 美元 | H9: =OFFSET(报关单!$I$1,ROW(报关单!I2)*3+17,0) -> 168
B10: 3 | C10: =OFFSET(报关单!$D$1,ROW(报关单!D3)*3+16,0) -> 球铃组合 | D10: =报关单!G27 -> 7 | E10: =报关单!H27 -> 盒 | F10: =报关单!I26 -> 3 | G10: =OFFSET(报关单!$I$1,ROW(报关单!I3)*3+18,0) -> 美元 | H10: =OFFSET(报关单!$I$1,ROW(报关单!I3)*3+17,0) -> 21
B11: 4 | C11: =OFFSET(报关单!$D$1,ROW(报关单!D4)*3+16,0) -> 落球塔 | D11: =报关单!G30 -> 2 | E11: =报关单!H30 -> 盒 | F11: =报关单!I29 -> 6 | G11: =OFFSET(报关单!$I$1,ROW(报关单!I4)*3+18,0) -> 美元 | H11: =OFFSET(报关单!$I$1,ROW(报关单!I4)*3+17,0) -> 12
B12: 5 | C12: =OFFSET(报关单!$D$1,ROW(报关单!D5)*3+16,0) -> 缝纫机 | D12: =报关单!G33 -> 2 | E12: =报关单!H33 -> 盒 | F12: =报关单!I32 -> 6 | G12: =OFFSET(报关单!$I$1,ROW(报关单!I5)*3+18,0) -> 美元 | H12: =OFFSET(报关单!$I$1,ROW(报关单!I5)*3+17,0) -> 12
B13: 6 | C13: =OFFSET(报关单!$D$1,ROW(报关单!D6)*3+16,0) -> 假泥鳅 | D13: =报关单!G36 -> 8 | E13: =报关单!H36 -> 盒 | F13: =报关单!I35 -> 2 | G13: =OFFSET(报关单!$I$1,ROW(报关单!I6)*3+18,0) -> 美元 | H13: =OFFSET(报关单!$I$1,ROW(报关单!I6)*3+17,0) -> 16
B14: 7 | C14: =OFFSET(报关单!$D$1,ROW(报关单!D7)*3+16,0) -> 立体拼图 | D14: =报关单!G39 -> 8 | E14: =报关单!H39 -> 盒 | F14: =报关单!I38 -> 2 | G14: =OFFSET(报关单!$I$1,ROW(报关单!I7)*3+18,0) -> 美元 | H14: =OFFSET(报关单!$I$1,ROW(报关单!I7)*3+17,0) -> 16
B15: 8 | C15: =OFFSET(报关单!$D$1,ROW(报关单!D8)*3+16,0) -> 升空火箭 | D15: =报关单!G42 -> 6 | E15: =报关单!H42 -> 盒 | F15: =报关单!I41 -> 9 | G15: =OFFSET(报关单!$I$1,ROW(报关单!I8)*3+18,0) -> 美元 | H15: =OFFSET(报关单!$I$1,ROW(报关单!I8)*3+17,0) -> 54
B16: 9 | C16: =OFFSET(报关单!$D$1,ROW(报关单!D9)*3+16,0) -> 谷雨小车 | D16: =报关单!G45 -> 14 | E16: =报关单!H45 -> 盒 | F16: =报关单!I44 -> 3 | G16: =OFFSET(报关单!$I$1,ROW(报关单!I9)*3+18,0) -> 美元 | H16: =OFFSET(报关单!$I$1,ROW(报关单!I9)*3+17,0) -> 42
B17: 10 | C17: =OFFSET(报关单!$D$1,ROW(报关单!D10)*3+16,0) -> 0 | D17: =报关单!G48 -> 0 | E17: =报关单!H48 -> 0 | F17: =报关单!I47 -> 0 | G17: =OFFSET(报关单!$I$1,ROW(报关单!I10)*3+18,0) -> 0 | H17: =OFFSET(报关单!$I$1,ROW(报关单!I10)*3+17,0) -> 0
B18: 11 | C18: =OFFSET(报关单!$D$1,ROW(报关单!D11)*3+16,0) -> 0 | D18: =报关单!G51 -> 0 | E18: =报关单!H51 -> 0 | F18: =报关单!I50 -> 0 | G18: =OFFSET(报关单!$I$1,ROW(报关单!I11)*3+18,0) -> 0 | H18: =OFFSET(报关单!$I$1,ROW(报关单!I11)*3+17,0) -> 0
B19: 12 | C19: =OFFSET(报关单!$D$1,ROW(报关单!D12)*3+16,0) -> 0 | D19: =报关单!G54 -> 0 | E19: =报关单!H54 -> 0 | F19: =报关单!I53 -> 0 | G19: =OFFSET(报关单!$I$1,ROW(报关单!I12)*3+18,0) -> 0 | H19: =OFFSET(报关单!$I$1,ROW(报关单!I12)*3+17,0) -> 0
B20: 13 | C20: =OFFSET(报关单!$D$1,ROW(报关单!D13)*3+16,0) -> 0 | D20: =报关单!G57 -> 0 | E20: =报关单!H57 -> 0 | F20: =报关单!I56 -> 0 | G20: =OFFSET(报关单!$I$1,ROW(报关单!I13)*3+18,0) -> 0 | H20: =OFFSET(报关单!$I$1,ROW(报关单!I13)*3+17,0) -> 0
B21: 14 | C21: =OFFSET(报关单!$D$1,ROW(报关单!D14)*3+16,0) -> 0 | D21: =报关单!G60 -> 0 | E21: =报关单!H60 -> 0 | F21: =报关单!I59 -> 0 | G21: =OFFSET(报关单!$I$1,ROW(报关单!I14)*3+18,0) -> 0 | H21: =OFFSET(报关单!$I$1,ROW(报关单!I14)*3+17,0) -> 0
B22: 15 | C22: =OFFSET(报关单!$D$1,ROW(报关单!D15)*3+16,0) -> 0 | D22: =报关单!G63 -> 0 | E22: =报关单!H63 -> 0 | F22: =报关单!I62 -> 0 | G22: =OFFSET(报关单!$I$1,ROW(报关单!I11)*3+18,0) -> 0 | H22: =OFFSET(报关单!$I$1,ROW(报关单!I15)*3+17,0) -> 0
B23: 16 | C23: =OFFSET(报关单!$D$1,ROW(报关单!D16)*3+16,0) -> 0 | D23: =报关单!G66 -> 0 | E23: =报关单!H66 -> 0 | F23: =报关单!I65 -> 0 | G23: =OFFSET(报关单!$I$1,ROW(报关单!I12)*3+18,0) -> 0 | H23: =OFFSET(报关单!$I$1,ROW(报关单!I16)*3+17,0) -> 0
B24: 17 | C24: =OFFSET(报关单!$D$1,ROW(报关单!D17)*3+16,0) -> 0 | D24: =报关单!G69 -> 0 | E24: =报关单!H69 -> 0 | F24: =报关单!I68 -> 0 | G24: =OFFSET(报关单!$I$1,ROW(报关单!I13)*3+18,0) -> 0 | H24: =OFFSET(报关单!$I$1,ROW(报关单!I17)*3+17,0) -> 0
B25: 18 | C25: =OFFSET(报关单!$D$1,ROW(报关单!D18)*3+16,0) -> 0 | D25: =报关单!G72 -> 0 | E25: =报关单!H72 -> 0 | F25: =报关单!I71 -> 0 | G25: =OFFSET(报关单!$I$1,ROW(报关单!I14)*3+18,0) -> 0 | H25: =OFFSET(报关单!$I$1,ROW(报关单!I18)*3+17,0) -> 0
C26: =OFFSET(报关单!$D$1,ROW(报关单!D19)*3+16,0) -> 0
A27: =IF(G27="CNY","总计人民币:",IF(G27="USD","总计美元: "," ")) | C27: =H27 -> 475 | F27: TOTAL: | G27: =G8 -> 美元 | H27: =SUM(H8:H26) -> 475
A28: 唛头 Marks | F28: 备注：
C34: .

Sheet 箱单
B2: 装 箱 单 PACKING LIST
F3: 日期 Date： | G3: =发票!G3 -> 46006
F4: 发票编号 Invoice No: | G4: =发票!G2 -> FBA19GTDMPSV
A5: 客户 To Messrs: | B5: =发票!C3 -> Amazon.com Services, Inc. | F5: 合同号 Contract No: | G5: =报关单!A10 -> FBA19GTDMPSV
B7: Shipped by | C7: 深圳 | D7: =报关单!E10 -> 美国 | F7: 付款条件 Terms of Payment: | G7: =报关单!I12 -> CNF
A9: 项号 Item.No. | B9: 货物名称及规格 Description | C9: 箱数： Pkg： | D9: 数量： Ge.Quantity | F9: 毛重(KG)： G.W.(KG): | G9: 净重(KG)： N.W.(KG):
A10: 1 | B10: =发票!C8 -> 手抓球 | C10: =报关单!G22 -> 4 | D10: =报关单!G21 -> 67 | E10: =报关单!H21 -> 盒 | F10: =报关单!R22 -> 0 | G10: =报关单!O22 -> 0
A11: 2 | B11: =发票!C9 -> 软积木 | C11: =报关单!G25 -> 4 | D11: =报关单!G24 -> 56 | E11: =报关单!H24 -> 盒 | F11: =报关单!R25 -> 0 | G11: =报关单!O25 -> 0
A12: 3 | B12: =发票!C10 -> 球铃组合 | C12: =报关单!G28 -> 1 | D12: =报关单!G27 -> 7 | E12: =报关单!H27 -> 盒 | F12: =报关单!R28 -> 0 | G12: =报关单!O28 -> 0
A13: 4 | B13: =发票!C11 -> 落球塔 | C13: =报关单!G31 -> 1 | D13: =报关单!G30 -> 2 | E13: =报关单!H30 -> 盒 | F13: =报关单!R31 -> 0 | G13: =报关单!O31 -> 0
A14: 5 | B14: =发票!C12 -> 缝纫机 | C14: =报关单!G34 -> 1 | D14: =报关单!G33 -> 2 | E14: =报关单!H33 -> 盒 | F14: =报关单!R34 -> 0 | G14: =报关单!O34 -> 0
A15: 6 | B15: =发票!C13 -> 假泥鳅 | C15: =报关单!G37 -> 1 | D15: =报关单!G36 -> 8 | E15: =报关单!H36 -> 盒 | F15: =报关单!R37 -> 26.38 | G15: =报关单!O37 -> 25.12
A16: 7 | B16: =发票!C14 -> 立体拼图 | C16: =报关单!G40 -> 1 | D16: =报关单!G39 -> 8 | E16: =报关单!H39 -> 盒 | F16: =报关单!R40 -> 0 | G16: =报关单!O40 -> 0
A17: 8 | B17: =发票!C15 -> 升空火箭 | C17: =报关单!G43 -> 1 | D17: =报关单!G42 -> 6 | E17: =报关单!H42 -> 盒 | F17: =报关单!R43 -> 0 | G17: =报关单!O43 -> 0
A18: 9 | B18: =发票!C16 -> 谷雨小车 | C18: =报关单!G46 -> 1 | D18: =报关单!G45 -> 14 | E18: =报关单!H45 -> 盒 | F18: =报关单!R46 -> 0 | G18: =报关单!O46 -> 0
A19: 10 | B19: =发票!C17 -> 0 | C19: =报关单!G49 -> 0 | D19: =报关单!G48 -> 0 | E19: =报关单!H48 -> 0 | F19: =报关单!R49 -> 0 | G19: =报关单!O49 -> 0
A20: 11 | B20: =发票!C18 -> 0 | C20: =报关单!G52 -> 0 | D20: =报关单!G51 -> 0 | E20: =报关单!H51 -> 0 | F20: =报关单!R52 -> 0 | G20: =报关单!O52 -> 0
A21: 12 | B21: =发票!C19 -> 0 | C21: =报关单!G55 -> 0 | D21: =报关单!G54 -> 0 | E21: =报关单!H54 -> 0 | F21: =报关单!R55 -> 0 | G21: =报关单!O55 -> 0
A22: 13 | B22: =发票!C20 -> 0 | C22: =报关单!G58 -> 0 | D22: =报关单!G57 -> 0 | E22: =报关单!H57 -> 0 | F22: =报关单!R58 -> 0 | G22: =报关单!O58 -> 0
A23: 14 | B23: =发票!C21 -> 0 | C23: =报关单!G61 -> 0 | D23: =报关单!G60 -> 0 | E23: =报关单!H60 -> 0 | F23: =报关单!R61 -> 0 | G23: =报关单!O61 -> 0
A24: 15 | B24: =发票!C22 -> 0 | C24: =报关单!G64 -> 0 | D24: =报关单!G63 -> 0 | E24: =报关单!H63 -> 0 | F24: =报关单!R64 -> 0 | G24: =报关单!O64 -> 0
A25: 16 | B25: =发票!C23 -> 0 | C25: =报关单!G67 -> 0 | D25: =报关单!G66 -> 0 | E25: =报关单!H66 -> 0 | F25: =报关单!R67 -> 0 | G25: =报关单!O67 -> 0
A26: 17 | B26: =发票!C24 -> 0 | C26: =报关单!G70 -> 0 | D26: =报关单!G69 -> 0 | E26: =报关单!H69 -> 0 | F26: =报关单!R70 -> 0 | G26: =报关单!O70 -> 0
A27: 18 | B27: =发票!C25 -> 0 | C27: =报关单!G73 -> 0 | D27: =报关单!G72 -> 0 | E27: =报关单!H72 -> 0 | F27: =报关单!R73 -> 0 | G27: =报关单!O73 -> 0
A28: 合计 Total | C28: =SUM(C10:C27) -> 15 | D28: =SUM(D10:D27) -> 170 | F28: =SUM(F10:F27) -> 26.38 | G28: =SUM(G10:G27) -> 25.12
A29: 唛头 Marks

Sheet 合同
B1: 合 同 SALES CONTRACT
B2: 卖 方： | C2: =报关单!V5 -> 0
B3: Sellers:
B4: 地 址： | C4: 深圳市南山区粤海街道麻岭社区高新中二道2号 深圳软件园1栋601-K
B5: Address: | F5: 合同号码
B6: 电 话： | C6: 0755-82323816 | D6: 传 真 | E6: 0755-22966213 | F6: Contract No: | G6: =报关单!A10 -> FBA19GTDMPSV
B7: TEL: | D7: FAX: | F7: 日 期
B8: 买 方： | C8: =箱单!B5 -> Amazon.com Services, Inc. | F8: Date: | G8: =发票!G3 -> 46006
B9: Buyers： | F9: 签约地点
B10: 地 址： | C10: 24300 Nandina Ave Moreno Valley, CA 92551-9534 US (ONT8) | F10: Signed at: | G10: 深圳
B11: Address: | F11: 成交方式： Trade Term: | G11: =报关单!V4 -> 0
B12: 电 话 | D12: 传 真 | E12: =报关单!Y10 -> 0
B13: TEL: | D13: FAX:
B14: 经买卖双方确认根据下列条款订立本合同
B15: This contract is made out by the Sellers and Buyers as per the following terms and conditions mutuilly confirmed:
B16: (1)货物名称 | D16: (2) 数 量 | E16: (3)单 位 | F16: (4)单价 | G16: (5) 金 额
B17: Name of commodity | D17: Quantity | E17: Unit | F17: Unit Price | G17: Amount
B18: =发票!C8 -> 手抓球 | D18: =发票!D8 -> 67 | E18: =发票!E8 -> 盒 | F18: =发票!F8 -> 2 | G18: =发票!G8 -> 美元 | H18: =发票!H8 -> 134
B19: =发票!C9 -> 软积木 | D19: =发票!D9 -> 56 | E19: =发票!E9 -> 盒 | F19: =发票!F9 -> 3 | G19: =发票!G9 -> 美元 | H19: =发票!H9 -> 168
B20: =发票!C10 -> 球铃组合 | D20: =发票!D10 -> 7 | E20: =发票!E10 -> 盒 | F20: =发票!F10 -> 3 | G20: =发票!G10 -> 美元 | H20: =发票!H10 -> 21
B21: =发票!C11 -> 落球塔 | D21: =发票!D11 -> 2 | E21: =发票!E11 -> 盒 | F21: =发票!F11 -> 6 | G21: =发票!G11 -> 美元 | H21: =发票!H11 -> 12
B22: =发票!C12 -> 缝纫机 | D22: =发票!D12 -> 2 | E22: =发票!E12 -> 盒 | F22: =发票!F12 -> 6 | G22: =发票!G12 -> 美元 | H22: =发票!H12 -> 12
B23: =发票!C13 -> 假泥鳅 | D23: =发票!D13 -> 8 | E23: =发票!E13 -> 盒 | F23: =发票!F13 -> 2 | G23: =发票!G13 -> 美元 | H23: =发票!H13 -> 16
B24: =发票!C14 -> 立体拼图 | D24: =发票!D14 -> 8 | E24: =发票!E14 -> 盒 | F24: =发票!F14 -> 2 | G24: =发票!G14 -> 美元 | H24: =发票!H14 -> 16
B25: =发票!C15 -> 升空火箭 | D25: =发票!D15 -> 6 | E25: =发票!E15 -> 盒 | F25: =发票!F15 -> 9 | G25: =发票!G15 -> 美元 | H25: =发票!H15 -> 54
B26: =发票!C16 -> 谷雨小车 | D26: =发票!D16 -> 14 | E26: =发票!E16 -> 盒 | F26: =发票!F16 -> 3 | G26: =发票!G16 -> 美元 | H26: =发票!H16 -> 42
B27: =发票!C17 -> 0 | D27: =发票!D17 -> 0 | E27: =发票!E17 -> 0 | F27: =发票!F17 -> 0 | G27: =发票!G17 -> 0 | H27: =发票!H17 -> 0
B28: =发票!C18 -> 0 | D28: =发票!D18 -> 0 | E28: =发票!E18 -> 0 | F28: =发票!F18 -> 0 | G28: =发票!G18 -> 0 | H28: =发票!H18 -> 0
B29: =发票!C19 -> 0 | D29: =发票!D19 -> 0 | E29: =发票!E19 -> 0 | F29: =发票!F19 -> 0 | G29: =发票!G19 -> 0 | H29: =发票!H19 -> 0
... B35: =发票!C25 -> 0 | D35: =发票!D25 -> 0 | E35: =发票!E25 -> 0 | F35: =发票!F25 -> 0 | G35: =发票!G25 -> 0 | H35: =发票!H25 -> 0
B36: =发票!C26 -> 0
B38: =发票!C28 -> 0
B40: =发票!C28 -> 0
B41: 数量及总值允许有 2 %的增减。 | F41: 总 值 | G41: =G18 -> 美元 | H41: =SUM(H18:I40) -> 475
B42: 2 % more or less both in amount and quantity allowed. | F42: Total Amount:
B43: (6)合同总值（大写） | D43: =IF(G41="CNY","总计人民币:",IF(G41="USD","总计美元: "," ")) | E43: =H41 -> 475
B44: Total Value in Word: FORTY TWO THOUSAND FOUR HUNDRED AND SEVENTY THREE AND CENTS TWENTY EIGHT ONLY.
B45: (7)包装及唛头 | D45: =报关单!A12 -> 纸箱包装
B46: Packing and shipping Marks:
B47: (8)装运期
...

Sheet 代理报关委托书
E3: 代 理 报 关 委 托 书
G5: 编号：□□□□□□□□□□□
C6: =报关单!V11 -> 0
B7: 我单位现 A (A逐票、B长期)委托贵公司代理 AB 等通关事宜。（A、填单申报 B、辅助查验 C、
B8: 垫缴税款 D、办理海关证明联 E、审批手册 F、核销手册 G、申办减免税手续 H、其他 ）详见《委托报关协
B9: 议》。
B10: 我单位保证遵守《海关法》和国家有关法规，保证所提供的情况真实、完整、单货相符，无侵犯他
B11: 人知识产权的行为。否则，愿承担相关法律责任。
B12: 本委托书有效期自签字之日起至 | E12: 2022 年 12 月 30 日止。
G13: 委托方（盖章）：
D15: 法定代表人或其授权签署《代理报关委托书》的人（签字）
H16: =TODAY()-1 -> 46210
E18: 委 托 报 关 协 议
B20: 为明确委托报关具体事项和各自责任，双方经平等协商签定协议如下：
B21: 委托方 | C21: =报关单!A4 -> 深圳市宴君跨境电商有限公司 | G21: 被委托方 | H21: =报关单!Y11 -> 0
B22: 主要货物名称 | C22: =发票!C8 -> 手抓球 | G22: *报关单编码
B23: HS编码 | C23: =报关单!B20 -> 9503008900 | G23: 收到单证日期 | H23: =TODAY() -> 46211
B24: 货物总价 | C24: =发票!G27 -> 美元 | D24: =发票!H27 -> 475 | G24: 收到单证情况 | H24: 合同□√ | I24: 发票□√
B25: 进出口日期 | C25: =TODAY()+1 -> 46212 | H25: 装箱清单□√ | I25: 提（运）单□
B26: 提单号 | H26: 加工贸易手册□ | I26: 许可证件□
B27: 贸易方式 | C27: =报关单!E8 -> 9810 | H27: 其他
B28: 原产地/货源地 | C28: =报关单!P20 -> 广东汕头 | G28: 报关收费 | H28: 人民币： 元
B29: 其他要求： | G29: 承诺说明：
B36: 背面所列通用条款是本协议不可分割的一部分，对本协议的签署构成了对背面通用条款的同意。 | G36: 背面所列通用条款是本协议不可分割的一部分，对本协议的签署构成了对背面通用条款的同意。
B39: 委托方业务签章： | G39: 被委托方业务签章：
B44: 经办人签章： | G44: 经办报关员签章：
B45: 联系电话： | E45: =TODAY()-1 -> 46210 | G45: 联系电话： | I45: =TODAY() -> 46211
C48: （白联：海关留存、黄联：被委托方留存、红联：委托方留存） | I48: 中国报关协会监制

Sheet 存仓委托书
A1: 存 仓 委 托 书
B2: 公 司:
A3: 我 公 司 拟 将 下 列 货 物 存 入 贵 公 司 出 口 监 管 仓 库.这 批 货 物 属:
A4: 口 一般贸易出口 口 加工贸易企业出口
A5: 货 物 名 称: | B5: =报关单!D20 -> 手抓球 | E5: #REF!
A6: 境 内 货 源 地: | B6: =报关单!P20 -> 广东汕头
A7: 规 格 及 包 装: | B7: =报关单!A12 -> 纸箱包装
A8: 数 量: | B8: =报关单!E12 -> 5 | D8: 件
A9: 重 量: | B9: =报关单!F12 -> 26.38 | D9: 千克
A10: 价 值: | B10: =报关单!I22 -> 美元 | C10: =发票!H27 -> 475
A11: 运 输 工 具: | B11: =报关单!G6 -> 0
A12: 出 境 口 岸: | B12: =报关单!O10 -> 0
A13: 存 放 期: | B13: 三个月
A14: 请即与海关联系,准予办理货物入仓手续。
A15: 特此委托
A18: 申请人地址： | B18: =报关单!V6 -> 0 | G18: 申请人签署:
A20: 电 话： | B20: =报关单!V7 -> 0 | G20: (公章)
A21: 传 真： | G21: =TODAY()-1 -> 46210

Sheet 申报要素清单
B1: 商品申报要素清单
A3: =报关单!A20 -> 1 | B3: =报关单!D20 -> 手抓球
B4: 申报要素：无
B5: =报关单!D21 -> 给孩子玩具for baby development
A6: =报关单!A23 -> 2 | B6: =报关单!D23 -> 软积木
B7: 申报要素：无
B8: =报关单!D24 -> 给孩子玩具for baby development
A9: =报关单!A26 -> 3 | B9: =报关单!D26 -> 球铃组合
B10: 申报要素：无
B11: =报关单!D27 -> 给孩子玩具for baby development
A12: =报关单!A29 -> 4 | B12: =报关单!D29 -> 落球塔
B13: 申报要素：无
B14: =报关单!D30 -> 给孩子玩具for baby development
A15: 5 | B15: =报关单!D35 -> 假泥鳅
B16: 申报要素：无
B17: =报关单!D36 -> for fishing钓鱼
A18: 6 | B18: =报关单!D38 -> 立体拼图
B19: 申报要素：无
B20: =报关单!D39 -> 给孩子玩具for baby development
A21: 7 | B21: =报关单!D62 -> 0
B22: 申报要素：无
B23: =报关单!D63 -> 0
A24: 8 | B24: =报关单!D71 -> 0
B25: 申报要素：无
B26: =报关单!D72 -> 0
A27: 9 | B27: =报关单!D74 -> 0
B28: 申报要素：无
B29: =报关单!D75 -> 0
A30: 10 | B30: =报关单!D77 -> 0
B31: 申报要素：无
B32: =报关单!D78 -> 0
A33: 11 | B33: =报关单!D80 -> 0
B34: 申报要素：无
B35: =报关单!D81 -> 0
A36: 12 | B36: =报关单!D83 -> 0
B37: 申报要素：无
B38: =报关单!D84 -> 0
A39: 13 | B39: =报关单!D86 -> 0
B40: 申报要素：无
B41: =报关单!D87 -> 0
...
